[2024-03-01T20:39:42.099+0000] {taskinstance.py:1956} INFO - Dependencies all met for dep_context=non-requeueable deps ti=<TaskInstance: with_bash.first_task manual__2024-03-01T20:37:39.621998+00:00 [queued]>
[2024-03-01T20:39:42.107+0000] {taskinstance.py:1956} INFO - Dependencies all met for dep_context=requeueable deps ti=<TaskInstance: with_bash.first_task manual__2024-03-01T20:37:39.621998+00:00 [queued]>
[2024-03-01T20:39:42.108+0000] {taskinstance.py:2170} INFO - Starting attempt 2 of 6
[2024-03-01T20:39:42.120+0000] {taskinstance.py:2191} INFO - Executing <Task(BashOperator): first_task> on 2024-03-01 20:37:39.621998+00:00
[2024-03-01T20:39:42.126+0000] {standard_task_runner.py:60} INFO - Started process 253 to run task
[2024-03-01T20:39:42.129+0000] {standard_task_runner.py:87} INFO - Running: ['***', 'tasks', 'run', 'with_bash', 'first_task', 'manual__2024-03-01T20:37:39.621998+00:00', '--job-id', '124', '--raw', '--subdir', 'DAGS_FOLDER/with_bash.py', '--cfg-path', '/tmp/tmppapcst4w']
[2024-03-01T20:39:42.131+0000] {standard_task_runner.py:88} INFO - Job 124: Subtask first_task
[2024-03-01T20:39:42.175+0000] {task_command.py:423} INFO - Running <TaskInstance: with_bash.first_task manual__2024-03-01T20:37:39.621998+00:00 [running]> on host 6a4f9e6ed399
[2024-03-01T20:39:42.237+0000] {taskinstance.py:2480} INFO - Exporting env vars: AIRFLOW_CTX_DAG_OWNER='***' AIRFLOW_CTX_DAG_ID='with_bash' AIRFLOW_CTX_TASK_ID='first_task' AIRFLOW_CTX_EXECUTION_DATE='2024-03-01T20:37:39.621998+00:00' AIRFLOW_CTX_TRY_NUMBER='2' AIRFLOW_CTX_DAG_RUN_ID='manual__2024-03-01T20:37:39.621998+00:00'
[2024-03-01T20:39:42.240+0000] {subprocess.py:63} INFO - Tmp dir root location: /tmp
[2024-03-01T20:39:42.240+0000] {subprocess.py:75} INFO - Running command: ['/usr/bin/bash', '-c', 'Hello World']
[2024-03-01T20:39:42.254+0000] {subprocess.py:86} INFO - Output:
[2024-03-01T20:39:42.255+0000] {subprocess.py:93} INFO - /usr/bin/bash: line 1: Hello: command not found
[2024-03-01T20:39:42.256+0000] {subprocess.py:97} INFO - Command exited with return code 127
[2024-03-01T20:39:42.266+0000] {taskinstance.py:2698} ERROR - Task failed with exception
Traceback (most recent call last):
  File "/home/airflow/.local/lib/python3.8/site-packages/airflow/models/taskinstance.py", line 433, in _execute_task
    result = execute_callable(context=context, **execute_callable_kwargs)
  File "/home/airflow/.local/lib/python3.8/site-packages/airflow/operators/bash.py", line 212, in execute
    raise AirflowException(
airflow.exceptions.AirflowException: Bash command failed. The command returned a non-zero exit code 127.
[2024-03-01T20:39:42.269+0000] {taskinstance.py:1138} INFO - Marking task as UP_FOR_RETRY. dag_id=with_bash, task_id=first_task, execution_date=20240301T203739, start_date=20240301T203942, end_date=20240301T203942
[2024-03-01T20:39:42.282+0000] {standard_task_runner.py:107} ERROR - Failed to execute job 124 for task first_task (Bash command failed. The command returned a non-zero exit code 127.; 253)
[2024-03-01T20:39:42.301+0000] {local_task_job_runner.py:234} INFO - Task exited with return code 1
[2024-03-01T20:39:42.318+0000] {taskinstance.py:3280} INFO - 0 downstream tasks scheduled from follow-on schedule check
