[2024-03-01T20:32:47.931+0000] {taskinstance.py:1956} INFO - Dependencies all met for dep_context=non-requeueable deps ti=<TaskInstance: with_bash.first_task scheduled__2024-02-12T00:00:00+00:00 [queued]>
[2024-03-01T20:32:47.939+0000] {taskinstance.py:1956} INFO - Dependencies all met for dep_context=requeueable deps ti=<TaskInstance: with_bash.first_task scheduled__2024-02-12T00:00:00+00:00 [queued]>
[2024-03-01T20:32:47.940+0000] {taskinstance.py:2170} INFO - Starting attempt 5 of 6
[2024-03-01T20:32:47.952+0000] {taskinstance.py:2191} INFO - Executing <Task(BashOperator): first_task> on 2024-02-12 00:00:00+00:00
[2024-03-01T20:32:47.958+0000] {standard_task_runner.py:60} INFO - Started process 57 to run task
[2024-03-01T20:32:47.961+0000] {standard_task_runner.py:87} INFO - Running: ['***', 'tasks', 'run', 'with_bash', 'first_task', 'scheduled__2024-02-12T00:00:00+00:00', '--job-id', '101', '--raw', '--subdir', 'DAGS_FOLDER/with_bash.py', '--cfg-path', '/tmp/tmpsu9lq95k']
[2024-03-01T20:32:47.964+0000] {standard_task_runner.py:88} INFO - Job 101: Subtask first_task
[2024-03-01T20:32:48.009+0000] {task_command.py:423} INFO - Running <TaskInstance: with_bash.first_task scheduled__2024-02-12T00:00:00+00:00 [running]> on host 6a4f9e6ed399
[2024-03-01T20:32:48.074+0000] {taskinstance.py:2480} INFO - Exporting env vars: AIRFLOW_CTX_DAG_OWNER='***' AIRFLOW_CTX_DAG_ID='with_bash' AIRFLOW_CTX_TASK_ID='first_task' AIRFLOW_CTX_EXECUTION_DATE='2024-02-12T00:00:00+00:00' AIRFLOW_CTX_TRY_NUMBER='5' AIRFLOW_CTX_DAG_RUN_ID='scheduled__2024-02-12T00:00:00+00:00'
[2024-03-01T20:32:48.077+0000] {subprocess.py:63} INFO - Tmp dir root location: /tmp
[2024-03-01T20:32:48.078+0000] {subprocess.py:75} INFO - Running command: ['/usr/bin/bash', '-c', 'Hello World']
[2024-03-01T20:32:48.089+0000] {subprocess.py:86} INFO - Output:
[2024-03-01T20:32:48.091+0000] {subprocess.py:93} INFO - /usr/bin/bash: line 1: Hello: command not found
[2024-03-01T20:32:48.091+0000] {subprocess.py:97} INFO - Command exited with return code 127
[2024-03-01T20:32:48.100+0000] {taskinstance.py:2698} ERROR - Task failed with exception
Traceback (most recent call last):
  File "/home/airflow/.local/lib/python3.8/site-packages/airflow/models/taskinstance.py", line 433, in _execute_task
    result = execute_callable(context=context, **execute_callable_kwargs)
  File "/home/airflow/.local/lib/python3.8/site-packages/airflow/operators/bash.py", line 212, in execute
    raise AirflowException(
airflow.exceptions.AirflowException: Bash command failed. The command returned a non-zero exit code 127.
[2024-03-01T20:32:48.103+0000] {taskinstance.py:1138} INFO - Marking task as UP_FOR_RETRY. dag_id=with_bash, task_id=first_task, execution_date=20240212T000000, start_date=20240301T203247, end_date=20240301T203248
[2024-03-01T20:32:48.114+0000] {standard_task_runner.py:107} ERROR - Failed to execute job 101 for task first_task (Bash command failed. The command returned a non-zero exit code 127.; 57)
[2024-03-01T20:32:48.134+0000] {local_task_job_runner.py:234} INFO - Task exited with return code 1
[2024-03-01T20:32:48.148+0000] {taskinstance.py:3280} INFO - 0 downstream tasks scheduled from follow-on schedule check
