[2024-03-01T20:38:55.178+0000] {taskinstance.py:1956} INFO - Dependencies all met for dep_context=non-requeueable deps ti=<TaskInstance: with_bash.first_task manual__2024-03-01T20:36:51.920625+00:00 [queued]>
[2024-03-01T20:38:55.187+0000] {taskinstance.py:1956} INFO - Dependencies all met for dep_context=requeueable deps ti=<TaskInstance: with_bash.first_task manual__2024-03-01T20:36:51.920625+00:00 [queued]>
[2024-03-01T20:38:55.188+0000] {taskinstance.py:2170} INFO - Starting attempt 2 of 6
[2024-03-01T20:38:55.201+0000] {taskinstance.py:2191} INFO - Executing <Task(BashOperator): first_task> on 2024-03-01 20:36:51.920625+00:00
[2024-03-01T20:38:55.210+0000] {standard_task_runner.py:60} INFO - Started process 239 to run task
[2024-03-01T20:38:55.215+0000] {standard_task_runner.py:87} INFO - Running: ['***', 'tasks', 'run', 'with_bash', 'first_task', 'manual__2024-03-01T20:36:51.920625+00:00', '--job-id', '122', '--raw', '--subdir', 'DAGS_FOLDER/with_bash.py', '--cfg-path', '/tmp/tmpimph1wii']
[2024-03-01T20:38:55.219+0000] {standard_task_runner.py:88} INFO - Job 122: Subtask first_task
[2024-03-01T20:38:55.283+0000] {task_command.py:423} INFO - Running <TaskInstance: with_bash.first_task manual__2024-03-01T20:36:51.920625+00:00 [running]> on host 6a4f9e6ed399
[2024-03-01T20:38:55.358+0000] {taskinstance.py:2480} INFO - Exporting env vars: AIRFLOW_CTX_DAG_OWNER='***' AIRFLOW_CTX_DAG_ID='with_bash' AIRFLOW_CTX_TASK_ID='first_task' AIRFLOW_CTX_EXECUTION_DATE='2024-03-01T20:36:51.920625+00:00' AIRFLOW_CTX_TRY_NUMBER='2' AIRFLOW_CTX_DAG_RUN_ID='manual__2024-03-01T20:36:51.920625+00:00'
[2024-03-01T20:38:55.361+0000] {subprocess.py:63} INFO - Tmp dir root location: /tmp
[2024-03-01T20:38:55.362+0000] {subprocess.py:75} INFO - Running command: ['/usr/bin/bash', '-c', 'Hello World']
[2024-03-01T20:38:55.377+0000] {subprocess.py:86} INFO - Output:
[2024-03-01T20:38:55.379+0000] {subprocess.py:93} INFO - /usr/bin/bash: line 1: Hello: command not found
[2024-03-01T20:38:55.379+0000] {subprocess.py:97} INFO - Command exited with return code 127
[2024-03-01T20:38:55.390+0000] {taskinstance.py:2698} ERROR - Task failed with exception
Traceback (most recent call last):
  File "/home/airflow/.local/lib/python3.8/site-packages/airflow/models/taskinstance.py", line 433, in _execute_task
    result = execute_callable(context=context, **execute_callable_kwargs)
  File "/home/airflow/.local/lib/python3.8/site-packages/airflow/operators/bash.py", line 212, in execute
    raise AirflowException(
airflow.exceptions.AirflowException: Bash command failed. The command returned a non-zero exit code 127.
[2024-03-01T20:38:55.394+0000] {taskinstance.py:1138} INFO - Marking task as UP_FOR_RETRY. dag_id=with_bash, task_id=first_task, execution_date=20240301T203651, start_date=20240301T203855, end_date=20240301T203855
[2024-03-01T20:38:55.407+0000] {standard_task_runner.py:107} ERROR - Failed to execute job 122 for task first_task (Bash command failed. The command returned a non-zero exit code 127.; 239)
[2024-03-01T20:38:55.428+0000] {local_task_job_runner.py:234} INFO - Task exited with return code 1
[2024-03-01T20:38:55.445+0000] {taskinstance.py:3280} INFO - 0 downstream tasks scheduled from follow-on schedule check
