[2024-03-03T04:46:28.833+0000] {taskinstance.py:1956} INFO - Dependencies all met for dep_context=non-requeueable deps ti=<TaskInstance: task1dag.archive_data manual__2024-03-03T04:38:35.470723+00:00 [queued]>
[2024-03-03T04:46:28.852+0000] {taskinstance.py:1956} INFO - Dependencies all met for dep_context=requeueable deps ti=<TaskInstance: task1dag.archive_data manual__2024-03-03T04:38:35.470723+00:00 [queued]>
[2024-03-03T04:46:28.854+0000] {taskinstance.py:2170} INFO - Starting attempt 1 of 2
[2024-03-03T04:46:28.879+0000] {taskinstance.py:2191} INFO - Executing <Task(PythonOperator): archive_data> on 2024-03-03 04:38:35.470723+00:00
[2024-03-03T04:46:28.892+0000] {standard_task_runner.py:60} INFO - Started process 564 to run task
[2024-03-03T04:46:28.897+0000] {standard_task_runner.py:87} INFO - Running: ['***', 'tasks', 'run', 'task1dag', 'archive_data', 'manual__2024-03-03T04:38:35.470723+00:00', '--job-id', '399', '--raw', '--subdir', 'DAGS_FOLDER/task1dag.py', '--cfg-path', '/tmp/tmpso0eppj1']
[2024-03-03T04:46:28.902+0000] {standard_task_runner.py:88} INFO - Job 399: Subtask archive_data
[2024-03-03T04:46:28.989+0000] {task_command.py:423} INFO - Running <TaskInstance: task1dag.archive_data manual__2024-03-03T04:38:35.470723+00:00 [running]> on host dde2eb23f30a
[2024-03-03T04:46:29.155+0000] {taskinstance.py:2480} INFO - Exporting env vars: AIRFLOW_CTX_DAG_OWNER='***' AIRFLOW_CTX_DAG_ID='task1dag' AIRFLOW_CTX_TASK_ID='archive_data' AIRFLOW_CTX_EXECUTION_DATE='2024-03-03T04:38:35.470723+00:00' AIRFLOW_CTX_TRY_NUMBER='1' AIRFLOW_CTX_DAG_RUN_ID='manual__2024-03-03T04:38:35.470723+00:00'
[2024-03-03T04:46:29.164+0000] {taskinstance.py:2698} ERROR - Task failed with exception
Traceback (most recent call last):
  File "/home/airflow/.local/lib/python3.8/site-packages/airflow/models/taskinstance.py", line 433, in _execute_task
    result = execute_callable(context=context, **execute_callable_kwargs)
  File "/home/airflow/.local/lib/python3.8/site-packages/airflow/operators/python.py", line 199, in execute
    return_value = self.execute_callable()
  File "/home/airflow/.local/lib/python3.8/site-packages/airflow/operators/python.py", line 216, in execute_callable
    return self.python_callable(*self.op_args, **self.op_kwargs)
  File "/opt/airflow/dags/task1dag.py", line 39, in zip_directory
    with zipfile.ZipFile(zip_filename, 'w') as zipf:
  File "/usr/local/lib/python3.8/zipfile.py", line 1251, in __init__
    self.fp = io.open(file, filemode)
FileNotFoundError: [Errno 2] No such file or directory: 'opt/airflow/output/data.zip'
[2024-03-03T04:46:29.189+0000] {taskinstance.py:1138} INFO - Marking task as UP_FOR_RETRY. dag_id=task1dag, task_id=archive_data, execution_date=20240303T043835, start_date=20240303T044628, end_date=20240303T044629
[2024-03-03T04:46:29.214+0000] {standard_task_runner.py:107} ERROR - Failed to execute job 399 for task archive_data ([Errno 2] No such file or directory: 'opt/airflow/output/data.zip'; 564)
[2024-03-03T04:46:29.271+0000] {local_task_job_runner.py:234} INFO - Task exited with return code 1
[2024-03-03T04:46:29.300+0000] {taskinstance.py:3280} INFO - 0 downstream tasks scheduled from follow-on schedule check
