[2024-03-01T20:29:28.371+0000] {taskinstance.py:1956} INFO - Dependencies all met for dep_context=non-requeueable deps ti=<TaskInstance: with_bash.first_task scheduled__2024-02-03T00:00:00+00:00 [queued]>
[2024-03-01T20:29:28.384+0000] {taskinstance.py:1956} INFO - Dependencies all met for dep_context=requeueable deps ti=<TaskInstance: with_bash.first_task scheduled__2024-02-03T00:00:00+00:00 [queued]>
[2024-03-01T20:29:28.385+0000] {taskinstance.py:2170} INFO - Starting attempt 4 of 6
[2024-03-01T20:29:28.411+0000] {taskinstance.py:2191} INFO - Executing <Task(BashOperator): first_task> on 2024-02-03 00:00:00+00:00
[2024-03-01T20:29:28.427+0000] {standard_task_runner.py:60} INFO - Started process 482 to run task
[2024-03-01T20:29:28.433+0000] {standard_task_runner.py:87} INFO - Running: ['***', 'tasks', 'run', 'with_bash', 'first_task', 'scheduled__2024-02-03T00:00:00+00:00', '--job-id', '74', '--raw', '--subdir', 'DAGS_FOLDER/with_bash.py', '--cfg-path', '/tmp/tmpobzy4bi_']
[2024-03-01T20:29:28.439+0000] {standard_task_runner.py:88} INFO - Job 74: Subtask first_task
[2024-03-01T20:29:28.518+0000] {task_command.py:423} INFO - Running <TaskInstance: with_bash.first_task scheduled__2024-02-03T00:00:00+00:00 [running]> on host 3ae7012c7157
[2024-03-01T20:29:28.625+0000] {taskinstance.py:2480} INFO - Exporting env vars: AIRFLOW_CTX_DAG_OWNER='***' AIRFLOW_CTX_DAG_ID='with_bash' AIRFLOW_CTX_TASK_ID='first_task' AIRFLOW_CTX_EXECUTION_DATE='2024-02-03T00:00:00+00:00' AIRFLOW_CTX_TRY_NUMBER='4' AIRFLOW_CTX_DAG_RUN_ID='scheduled__2024-02-03T00:00:00+00:00'
[2024-03-01T20:29:28.631+0000] {subprocess.py:63} INFO - Tmp dir root location: /tmp
[2024-03-01T20:29:28.632+0000] {subprocess.py:75} INFO - Running command: ['/usr/bin/bash', '-c', 'Hello World']
[2024-03-01T20:29:28.659+0000] {subprocess.py:86} INFO - Output:
[2024-03-01T20:29:28.662+0000] {subprocess.py:93} INFO - /usr/bin/bash: line 1: Hello: command not found
[2024-03-01T20:29:28.663+0000] {subprocess.py:97} INFO - Command exited with return code 127
[2024-03-01T20:29:28.680+0000] {taskinstance.py:2698} ERROR - Task failed with exception
Traceback (most recent call last):
  File "/home/airflow/.local/lib/python3.8/site-packages/airflow/models/taskinstance.py", line 433, in _execute_task
    result = execute_callable(context=context, **execute_callable_kwargs)
  File "/home/airflow/.local/lib/python3.8/site-packages/airflow/operators/bash.py", line 212, in execute
    raise AirflowException(
airflow.exceptions.AirflowException: Bash command failed. The command returned a non-zero exit code 127.
[2024-03-01T20:29:28.689+0000] {taskinstance.py:1138} INFO - Marking task as UP_FOR_RETRY. dag_id=with_bash, task_id=first_task, execution_date=20240203T000000, start_date=20240301T202928, end_date=20240301T202928
[2024-03-01T20:29:28.717+0000] {standard_task_runner.py:107} ERROR - Failed to execute job 74 for task first_task (Bash command failed. The command returned a non-zero exit code 127.; 482)
[2024-03-01T20:29:28.767+0000] {local_task_job_runner.py:234} INFO - Task exited with return code 1
[2024-03-01T20:29:28.821+0000] {taskinstance.py:3280} INFO - 0 downstream tasks scheduled from follow-on schedule check
