[2024-03-09T20:59:12.720+0000] {taskinstance.py:1956} INFO - Dependencies all met for dep_context=non-requeueable deps ti=<TaskInstance: task2dag.unzip_task manual__2024-03-09T20:59:04.821478+00:00 [queued]>
[2024-03-09T20:59:12.729+0000] {taskinstance.py:1956} INFO - Dependencies all met for dep_context=requeueable deps ti=<TaskInstance: task2dag.unzip_task manual__2024-03-09T20:59:04.821478+00:00 [queued]>
[2024-03-09T20:59:12.730+0000] {taskinstance.py:2170} INFO - Starting attempt 1 of 2
[2024-03-09T20:59:12.743+0000] {taskinstance.py:2191} INFO - Executing <Task(PythonOperator): unzip_task> on 2024-03-09 20:59:04.821478+00:00
[2024-03-09T20:59:12.754+0000] {standard_task_runner.py:60} INFO - Started process 252 to run task
[2024-03-09T20:59:12.757+0000] {standard_task_runner.py:87} INFO - Running: ['***', 'tasks', 'run', 'task2dag', 'unzip_task', 'manual__2024-03-09T20:59:04.821478+00:00', '--job-id', '793', '--raw', '--subdir', 'DAGS_FOLDER/task2dag.py', '--cfg-path', '/tmp/tmp1t7mp_y1']
[2024-03-09T20:59:12.758+0000] {standard_task_runner.py:88} INFO - Job 793: Subtask unzip_task
[2024-03-09T20:59:12.798+0000] {task_command.py:423} INFO - Running <TaskInstance: task2dag.unzip_task manual__2024-03-09T20:59:04.821478+00:00 [running]> on host 9268fe474086
[2024-03-09T20:59:12.867+0000] {taskinstance.py:2480} INFO - Exporting env vars: AIRFLOW_CTX_DAG_OWNER='***' AIRFLOW_CTX_DAG_ID='task2dag' AIRFLOW_CTX_TASK_ID='unzip_task' AIRFLOW_CTX_EXECUTION_DATE='2024-03-09T20:59:04.821478+00:00' AIRFLOW_CTX_TRY_NUMBER='1' AIRFLOW_CTX_DAG_RUN_ID='manual__2024-03-09T20:59:04.821478+00:00'
[2024-03-09T20:59:12.868+0000] {taskinstance.py:2698} ERROR - Task failed with exception
Traceback (most recent call last):
  File "/home/airflow/.local/lib/python3.8/site-packages/airflow/models/taskinstance.py", line 433, in _execute_task
    result = execute_callable(context=context, **execute_callable_kwargs)
  File "/home/airflow/.local/lib/python3.8/site-packages/airflow/operators/python.py", line 199, in execute
    return_value = self.execute_callable()
  File "/home/airflow/.local/lib/python3.8/site-packages/airflow/operators/python.py", line 216, in execute_callable
    return self.python_callable(*self.op_args, **self.op_kwargs)
TypeError: unzip_files() missing 2 required positional arguments: 'file_path' and 'extract_path'
[2024-03-09T20:59:12.875+0000] {taskinstance.py:1138} INFO - Marking task as UP_FOR_RETRY. dag_id=task2dag, task_id=unzip_task, execution_date=20240309T205904, start_date=20240309T205912, end_date=20240309T205912
[2024-03-09T20:59:12.885+0000] {standard_task_runner.py:107} ERROR - Failed to execute job 793 for task unzip_task (unzip_files() missing 2 required positional arguments: 'file_path' and 'extract_path'; 252)
[2024-03-09T20:59:12.929+0000] {local_task_job_runner.py:234} INFO - Task exited with return code 1
[2024-03-09T20:59:12.954+0000] {taskinstance.py:3280} INFO - 0 downstream tasks scheduled from follow-on schedule check
