[2024-03-02T11:03:32.731+0000] {taskinstance.py:1956} INFO - Dependencies all met for dep_context=non-requeueable deps ti=<TaskInstance: task_1_dag.scrape_data_2022 manual__2024-03-02T11:03:27.258692+00:00 [queued]>
[2024-03-02T11:03:32.748+0000] {taskinstance.py:1956} INFO - Dependencies all met for dep_context=requeueable deps ti=<TaskInstance: task_1_dag.scrape_data_2022 manual__2024-03-02T11:03:27.258692+00:00 [queued]>
[2024-03-02T11:03:32.748+0000] {taskinstance.py:2170} INFO - Starting attempt 1 of 2
[2024-03-02T11:03:32.771+0000] {taskinstance.py:2191} INFO - Executing <Task(PythonOperator): scrape_data_2022> on 2024-03-02 11:03:27.258692+00:00
[2024-03-02T11:03:32.779+0000] {standard_task_runner.py:60} INFO - Started process 86 to run task
[2024-03-02T11:03:32.784+0000] {standard_task_runner.py:87} INFO - Running: ['***', 'tasks', 'run', 'task_1_dag', 'scrape_data_2022', 'manual__2024-03-02T11:03:27.258692+00:00', '--job-id', '132', '--raw', '--subdir', 'DAGS_FOLDER/check2.py', '--cfg-path', '/tmp/tmpffnozw6d']
[2024-03-02T11:03:32.788+0000] {standard_task_runner.py:88} INFO - Job 132: Subtask scrape_data_2022
[2024-03-02T11:03:32.864+0000] {task_command.py:423} INFO - Running <TaskInstance: task_1_dag.scrape_data_2022 manual__2024-03-02T11:03:27.258692+00:00 [running]> on host e13f4e34e115
[2024-03-02T11:03:32.989+0000] {taskinstance.py:2480} INFO - Exporting env vars: AIRFLOW_CTX_DAG_OWNER='***' AIRFLOW_CTX_DAG_ID='task_1_dag' AIRFLOW_CTX_TASK_ID='scrape_data_2022' AIRFLOW_CTX_EXECUTION_DATE='2024-03-02T11:03:27.258692+00:00' AIRFLOW_CTX_TRY_NUMBER='1' AIRFLOW_CTX_DAG_RUN_ID='manual__2024-03-02T11:03:27.258692+00:00'
[2024-03-02T11:03:32.993+0000] {logging_mixin.py:188} INFO - cwd: /opt/***
[2024-03-02T11:03:33.001+0000] {taskinstance.py:2698} ERROR - Task failed with exception
Traceback (most recent call last):
  File "/home/airflow/.local/lib/python3.8/site-packages/airflow/models/taskinstance.py", line 433, in _execute_task
    result = execute_callable(context=context, **execute_callable_kwargs)
  File "/home/airflow/.local/lib/python3.8/site-packages/airflow/operators/python.py", line 199, in execute
    return_value = self.execute_callable()
  File "/home/airflow/.local/lib/python3.8/site-packages/airflow/operators/python.py", line 216, in execute_callable
    return self.python_callable(*self.op_args, **self.op_kwargs)
  File "/opt/airflow/dags/check2.py", line 13, in scrape_data
    os.makedirs(f'/data/{year}', exist_ok=True)
  File "/usr/local/lib/python3.8/os.py", line 213, in makedirs
    makedirs(head, exist_ok=exist_ok)
  File "/usr/local/lib/python3.8/os.py", line 223, in makedirs
    mkdir(name, mode)
PermissionError: [Errno 13] Permission denied: '/data'
[2024-03-02T11:03:33.021+0000] {taskinstance.py:1138} INFO - Marking task as UP_FOR_RETRY. dag_id=task_1_dag, task_id=scrape_data_2022, execution_date=20240302T110327, start_date=20240302T110332, end_date=20240302T110333
[2024-03-02T11:03:33.049+0000] {standard_task_runner.py:107} ERROR - Failed to execute job 132 for task scrape_data_2022 ([Errno 13] Permission denied: '/data'; 86)
[2024-03-02T11:03:33.077+0000] {local_task_job_runner.py:234} INFO - Task exited with return code 1
[2024-03-02T11:03:33.107+0000] {taskinstance.py:3280} INFO - 0 downstream tasks scheduled from follow-on schedule check
