[2024-03-09T18:11:05.594+0000] {taskinstance.py:1956} INFO - Dependencies all met for dep_context=non-requeueable deps ti=<TaskInstance: task1dag.scrape_data_2015 manual__2024-03-09T18:10:59.239304+00:00 [queued]>
[2024-03-09T18:11:05.617+0000] {taskinstance.py:1956} INFO - Dependencies all met for dep_context=requeueable deps ti=<TaskInstance: task1dag.scrape_data_2015 manual__2024-03-09T18:10:59.239304+00:00 [queued]>
[2024-03-09T18:11:05.619+0000] {taskinstance.py:2170} INFO - Starting attempt 1 of 1
[2024-03-09T18:11:05.660+0000] {taskinstance.py:2191} INFO - Executing <Task(PythonOperator): scrape_data_2015> on 2024-03-09 18:10:59.239304+00:00
[2024-03-09T18:11:05.679+0000] {standard_task_runner.py:60} INFO - Started process 2621 to run task
[2024-03-09T18:11:05.690+0000] {standard_task_runner.py:87} INFO - Running: ['***', 'tasks', 'run', 'task1dag', 'scrape_data_2015', 'manual__2024-03-09T18:10:59.239304+00:00', '--job-id', '485', '--raw', '--subdir', 'DAGS_FOLDER/task1dag.py', '--cfg-path', '/tmp/tmp9du6mkhj']
[2024-03-09T18:11:05.700+0000] {standard_task_runner.py:88} INFO - Job 485: Subtask scrape_data_2015
[2024-03-09T18:11:05.849+0000] {task_command.py:423} INFO - Running <TaskInstance: task1dag.scrape_data_2015 manual__2024-03-09T18:10:59.239304+00:00 [running]> on host 9ce19ff1a6f4
[2024-03-09T18:11:06.116+0000] {taskinstance.py:2480} INFO - Exporting env vars: AIRFLOW_CTX_DAG_OWNER='***' AIRFLOW_CTX_DAG_ID='task1dag' AIRFLOW_CTX_TASK_ID='scrape_data_2015' AIRFLOW_CTX_EXECUTION_DATE='2024-03-09T18:10:59.239304+00:00' AIRFLOW_CTX_TRY_NUMBER='1' AIRFLOW_CTX_DAG_RUN_ID='manual__2024-03-09T18:10:59.239304+00:00'
[2024-03-09T18:11:06.121+0000] {logging_mixin.py:188} INFO - cwd: /opt/***
[2024-03-09T18:11:43.272+0000] {taskinstance.py:2698} ERROR - Task failed with exception
Traceback (most recent call last):
  File "/home/airflow/.local/lib/python3.8/site-packages/urllib3/connection.py", line 174, in _new_conn
    conn = connection.create_connection(
  File "/home/airflow/.local/lib/python3.8/site-packages/urllib3/util/connection.py", line 72, in create_connection
    for res in socket.getaddrinfo(host, port, family, socket.SOCK_STREAM):
  File "/usr/local/lib/python3.8/socket.py", line 918, in getaddrinfo
    for res in _socket.getaddrinfo(host, port, family, type, proto, flags):
socket.gaierror: [Errno -3] Temporary failure in name resolution

During handling of the above exception, another exception occurred:

Traceback (most recent call last):
  File "/home/airflow/.local/lib/python3.8/site-packages/urllib3/connectionpool.py", line 715, in urlopen
    httplib_response = self._make_request(
  File "/home/airflow/.local/lib/python3.8/site-packages/urllib3/connectionpool.py", line 404, in _make_request
    self._validate_conn(conn)
  File "/home/airflow/.local/lib/python3.8/site-packages/urllib3/connectionpool.py", line 1058, in _validate_conn
    conn.connect()
  File "/home/airflow/.local/lib/python3.8/site-packages/urllib3/connection.py", line 363, in connect
    self.sock = conn = self._new_conn()
  File "/home/airflow/.local/lib/python3.8/site-packages/urllib3/connection.py", line 186, in _new_conn
    raise NewConnectionError(
urllib3.exceptions.NewConnectionError: <urllib3.connection.HTTPSConnection object at 0x7f0c0fd48b20>: Failed to establish a new connection: [Errno -3] Temporary failure in name resolution

During handling of the above exception, another exception occurred:

Traceback (most recent call last):
  File "/home/airflow/.local/lib/python3.8/site-packages/requests/adapters.py", line 486, in send
    resp = conn.urlopen(
  File "/home/airflow/.local/lib/python3.8/site-packages/urllib3/connectionpool.py", line 799, in urlopen
    retries = retries.increment(
  File "/home/airflow/.local/lib/python3.8/site-packages/urllib3/util/retry.py", line 592, in increment
    raise MaxRetryError(_pool, url, error or ResponseError(cause))
urllib3.exceptions.MaxRetryError: HTTPSConnectionPool(host='www.ncei.noaa.gov', port=443): Max retries exceeded with url: /data/local-climatological-data/access/2015/00707099999.csv (Caused by NewConnectionError('<urllib3.connection.HTTPSConnection object at 0x7f0c0fd48b20>: Failed to establish a new connection: [Errno -3] Temporary failure in name resolution'))

During handling of the above exception, another exception occurred:

Traceback (most recent call last):
  File "/home/airflow/.local/lib/python3.8/site-packages/airflow/models/taskinstance.py", line 433, in _execute_task
    result = execute_callable(context=context, **execute_callable_kwargs)
  File "/home/airflow/.local/lib/python3.8/site-packages/airflow/operators/python.py", line 199, in execute
    return_value = self.execute_callable()
  File "/home/airflow/.local/lib/python3.8/site-packages/airflow/operators/python.py", line 216, in execute_callable
    return self.python_callable(*self.op_args, **self.op_kwargs)
  File "/opt/airflow/dags/task1dag.py", line 28, in scrape_data
    res = requests.get(file_url)
  File "/home/airflow/.local/lib/python3.8/site-packages/requests/api.py", line 73, in get
    return request("get", url, params=params, **kwargs)
  File "/home/airflow/.local/lib/python3.8/site-packages/requests/api.py", line 59, in request
    return session.request(method=method, url=url, **kwargs)
  File "/home/airflow/.local/lib/python3.8/site-packages/requests/sessions.py", line 589, in request
    resp = self.send(prep, **send_kwargs)
  File "/home/airflow/.local/lib/python3.8/site-packages/requests/sessions.py", line 703, in send
    r = adapter.send(request, **kwargs)
  File "/home/airflow/.local/lib/python3.8/site-packages/requests/adapters.py", line 519, in send
    raise ConnectionError(e, request=request)
requests.exceptions.ConnectionError: HTTPSConnectionPool(host='www.ncei.noaa.gov', port=443): Max retries exceeded with url: /data/local-climatological-data/access/2015/00707099999.csv (Caused by NewConnectionError('<urllib3.connection.HTTPSConnection object at 0x7f0c0fd48b20>: Failed to establish a new connection: [Errno -3] Temporary failure in name resolution'))
[2024-03-09T18:11:43.548+0000] {taskinstance.py:1138} INFO - Marking task as FAILED. dag_id=task1dag, task_id=scrape_data_2015, execution_date=20240309T181059, start_date=20240309T181105, end_date=20240309T181143
[2024-03-09T18:11:43.743+0000] {standard_task_runner.py:107} ERROR - Failed to execute job 485 for task scrape_data_2015 (HTTPSConnectionPool(host='www.ncei.noaa.gov', port=443): Max retries exceeded with url: /data/local-climatological-data/access/2015/00707099999.csv (Caused by NewConnectionError('<urllib3.connection.HTTPSConnection object at 0x7f0c0fd48b20>: Failed to establish a new connection: [Errno -3] Temporary failure in name resolution')); 2621)
[2024-03-09T18:11:43.865+0000] {local_task_job_runner.py:234} INFO - Task exited with return code 1
[2024-03-09T18:11:44.272+0000] {taskinstance.py:3280} INFO - 0 downstream tasks scheduled from follow-on schedule check
