[2024-03-09T19:50:52.193+0000] {taskinstance.py:1956} INFO - Dependencies all met for dep_context=non-requeueable deps ti=<TaskInstance: task1dag.scrape_data_2022 manual__2024-03-09T19:48:34.038592+00:00 [queued]>
[2024-03-09T19:50:52.202+0000] {taskinstance.py:1956} INFO - Dependencies all met for dep_context=requeueable deps ti=<TaskInstance: task1dag.scrape_data_2022 manual__2024-03-09T19:48:34.038592+00:00 [queued]>
[2024-03-09T19:50:52.203+0000] {taskinstance.py:2170} INFO - Starting attempt 1 of 1
[2024-03-09T19:50:52.217+0000] {taskinstance.py:2191} INFO - Executing <Task(PythonOperator): scrape_data_2022> on 2024-03-09 19:48:34.038592+00:00
[2024-03-09T19:50:52.226+0000] {standard_task_runner.py:60} INFO - Started process 666 to run task
[2024-03-09T19:50:52.228+0000] {standard_task_runner.py:87} INFO - Running: ['***', 'tasks', 'run', 'task1dag', 'scrape_data_2022', 'manual__2024-03-09T19:48:34.038592+00:00', '--job-id', '567', '--raw', '--subdir', 'DAGS_FOLDER/task1dag.py', '--cfg-path', '/tmp/tmpcp67bffg']
[2024-03-09T19:50:52.230+0000] {standard_task_runner.py:88} INFO - Job 567: Subtask scrape_data_2022
[2024-03-09T19:50:52.280+0000] {task_command.py:423} INFO - Running <TaskInstance: task1dag.scrape_data_2022 manual__2024-03-09T19:48:34.038592+00:00 [running]> on host 800ade8643a5
[2024-03-09T19:50:52.353+0000] {taskinstance.py:2480} INFO - Exporting env vars: AIRFLOW_CTX_DAG_OWNER='***' AIRFLOW_CTX_DAG_ID='task1dag' AIRFLOW_CTX_TASK_ID='scrape_data_2022' AIRFLOW_CTX_EXECUTION_DATE='2024-03-09T19:48:34.038592+00:00' AIRFLOW_CTX_TRY_NUMBER='1' AIRFLOW_CTX_DAG_RUN_ID='manual__2024-03-09T19:48:34.038592+00:00'
[2024-03-09T19:50:52.356+0000] {logging_mixin.py:188} INFO - cwd: /opt/***
[2024-03-09T19:51:31.362+0000] {taskinstance.py:2698} ERROR - Task failed with exception
Traceback (most recent call last):
  File "/home/airflow/.local/lib/python3.8/site-packages/urllib3/connectionpool.py", line 715, in urlopen
    httplib_response = self._make_request(
  File "/home/airflow/.local/lib/python3.8/site-packages/urllib3/connectionpool.py", line 404, in _make_request
    self._validate_conn(conn)
  File "/home/airflow/.local/lib/python3.8/site-packages/urllib3/connectionpool.py", line 1058, in _validate_conn
    conn.connect()
  File "/home/airflow/.local/lib/python3.8/site-packages/urllib3/connection.py", line 419, in connect
    self.sock = ssl_wrap_socket(
  File "/home/airflow/.local/lib/python3.8/site-packages/urllib3/util/ssl_.py", line 449, in ssl_wrap_socket
    ssl_sock = _ssl_wrap_socket_impl(
  File "/home/airflow/.local/lib/python3.8/site-packages/urllib3/util/ssl_.py", line 493, in _ssl_wrap_socket_impl
    return ssl_context.wrap_socket(sock, server_hostname=server_hostname)
  File "/usr/local/lib/python3.8/ssl.py", line 500, in wrap_socket
    return self.sslsocket_class._create(
  File "/usr/local/lib/python3.8/ssl.py", line 1073, in _create
    self.do_handshake()
  File "/usr/local/lib/python3.8/ssl.py", line 1342, in do_handshake
    self._sslobj.do_handshake()
ssl.SSLZeroReturnError: TLS/SSL connection has been closed (EOF) (_ssl.c:1131)

During handling of the above exception, another exception occurred:

Traceback (most recent call last):
  File "/home/airflow/.local/lib/python3.8/site-packages/requests/adapters.py", line 486, in send
    resp = conn.urlopen(
  File "/home/airflow/.local/lib/python3.8/site-packages/urllib3/connectionpool.py", line 799, in urlopen
    retries = retries.increment(
  File "/home/airflow/.local/lib/python3.8/site-packages/urllib3/util/retry.py", line 592, in increment
    raise MaxRetryError(_pool, url, error or ResponseError(cause))
urllib3.exceptions.MaxRetryError: HTTPSConnectionPool(host='www.ncei.noaa.gov', port=443): Max retries exceeded with url: /data/local-climatological-data/access/2022/01001099999.csv (Caused by SSLError(SSLZeroReturnError(6, 'TLS/SSL connection has been closed (EOF) (_ssl.c:1131)')))

During handling of the above exception, another exception occurred:

Traceback (most recent call last):
  File "/home/airflow/.local/lib/python3.8/site-packages/airflow/models/taskinstance.py", line 433, in _execute_task
    result = execute_callable(context=context, **execute_callable_kwargs)
  File "/home/airflow/.local/lib/python3.8/site-packages/airflow/operators/python.py", line 199, in execute
    return_value = self.execute_callable()
  File "/home/airflow/.local/lib/python3.8/site-packages/airflow/operators/python.py", line 216, in execute_callable
    return self.python_callable(*self.op_args, **self.op_kwargs)
  File "/opt/airflow/dags/task1dag.py", line 31, in scrape_data
    res = requests.get(file_url)
  File "/home/airflow/.local/lib/python3.8/site-packages/requests/api.py", line 73, in get
    return request("get", url, params=params, **kwargs)
  File "/home/airflow/.local/lib/python3.8/site-packages/requests/api.py", line 59, in request
    return session.request(method=method, url=url, **kwargs)
  File "/home/airflow/.local/lib/python3.8/site-packages/requests/sessions.py", line 589, in request
    resp = self.send(prep, **send_kwargs)
  File "/home/airflow/.local/lib/python3.8/site-packages/requests/sessions.py", line 703, in send
    r = adapter.send(request, **kwargs)
  File "/home/airflow/.local/lib/python3.8/site-packages/requests/adapters.py", line 517, in send
    raise SSLError(e, request=request)
requests.exceptions.SSLError: HTTPSConnectionPool(host='www.ncei.noaa.gov', port=443): Max retries exceeded with url: /data/local-climatological-data/access/2022/01001099999.csv (Caused by SSLError(SSLZeroReturnError(6, 'TLS/SSL connection has been closed (EOF) (_ssl.c:1131)')))
[2024-03-09T19:51:31.626+0000] {taskinstance.py:1138} INFO - Marking task as FAILED. dag_id=task1dag, task_id=scrape_data_2022, execution_date=20240309T194834, start_date=20240309T195052, end_date=20240309T195131
[2024-03-09T19:51:31.733+0000] {standard_task_runner.py:107} ERROR - Failed to execute job 567 for task scrape_data_2022 (HTTPSConnectionPool(host='www.ncei.noaa.gov', port=443): Max retries exceeded with url: /data/local-climatological-data/access/2022/01001099999.csv (Caused by SSLError(SSLZeroReturnError(6, 'TLS/SSL connection has been closed (EOF) (_ssl.c:1131)'))); 666)
[2024-03-09T19:51:31.767+0000] {local_task_job_runner.py:234} INFO - Task exited with return code 1
[2024-03-09T19:51:31.834+0000] {taskinstance.py:3280} INFO - 0 downstream tasks scheduled from follow-on schedule check
