[2024-03-02T14:16:27.039+0000] {taskinstance.py:1956} INFO - Dependencies all met for dep_context=non-requeueable deps ti=<TaskInstance: task_1_dag.archive_data manual__2024-03-02T14:15:52.667957+00:00 [queued]>
[2024-03-02T14:16:27.046+0000] {taskinstance.py:1956} INFO - Dependencies all met for dep_context=requeueable deps ti=<TaskInstance: task_1_dag.archive_data manual__2024-03-02T14:15:52.667957+00:00 [queued]>
[2024-03-02T14:16:27.047+0000] {taskinstance.py:2170} INFO - Starting attempt 1 of 2
[2024-03-02T14:16:27.061+0000] {taskinstance.py:2191} INFO - Executing <Task(BashOperator): archive_data> on 2024-03-02 14:15:52.667957+00:00
[2024-03-02T14:16:27.069+0000] {standard_task_runner.py:60} INFO - Started process 197 to run task
[2024-03-02T14:16:27.071+0000] {standard_task_runner.py:87} INFO - Running: ['***', 'tasks', 'run', 'task_1_dag', 'archive_data', 'manual__2024-03-02T14:15:52.667957+00:00', '--job-id', '351', '--raw', '--subdir', 'DAGS_FOLDER/check2.py', '--cfg-path', '/tmp/tmp2p702smg']
[2024-03-02T14:16:27.073+0000] {standard_task_runner.py:88} INFO - Job 351: Subtask archive_data
[2024-03-02T14:16:27.109+0000] {task_command.py:423} INFO - Running <TaskInstance: task_1_dag.archive_data manual__2024-03-02T14:15:52.667957+00:00 [running]> on host 64d00280a601
[2024-03-02T14:16:27.174+0000] {taskinstance.py:2480} INFO - Exporting env vars: AIRFLOW_CTX_DAG_OWNER='***' AIRFLOW_CTX_DAG_ID='task_1_dag' AIRFLOW_CTX_TASK_ID='archive_data' AIRFLOW_CTX_EXECUTION_DATE='2024-03-02T14:15:52.667957+00:00' AIRFLOW_CTX_TRY_NUMBER='1' AIRFLOW_CTX_DAG_RUN_ID='manual__2024-03-02T14:15:52.667957+00:00'
[2024-03-02T14:16:27.176+0000] {subprocess.py:63} INFO - Tmp dir root location: /tmp
[2024-03-02T14:16:27.177+0000] {subprocess.py:75} INFO - Running command: ['/usr/bin/bash', '-c', 'mkdir -p /opt/***/output && zip -r /opt/***/output/data.zip /opt/***/data']
[2024-03-02T14:16:27.190+0000] {subprocess.py:86} INFO - Output:
[2024-03-02T14:16:27.196+0000] {subprocess.py:93} INFO - /usr/bin/bash: line 1: zip: command not found
[2024-03-02T14:16:27.196+0000] {subprocess.py:97} INFO - Command exited with return code 127
[2024-03-02T14:16:27.205+0000] {taskinstance.py:2698} ERROR - Task failed with exception
Traceback (most recent call last):
  File "/home/airflow/.local/lib/python3.8/site-packages/airflow/models/taskinstance.py", line 433, in _execute_task
    result = execute_callable(context=context, **execute_callable_kwargs)
  File "/home/airflow/.local/lib/python3.8/site-packages/airflow/operators/bash.py", line 212, in execute
    raise AirflowException(
airflow.exceptions.AirflowException: Bash command failed. The command returned a non-zero exit code 127.
[2024-03-02T14:16:27.208+0000] {taskinstance.py:1138} INFO - Marking task as UP_FOR_RETRY. dag_id=task_1_dag, task_id=archive_data, execution_date=20240302T141552, start_date=20240302T141627, end_date=20240302T141627
[2024-03-02T14:16:27.219+0000] {standard_task_runner.py:107} ERROR - Failed to execute job 351 for task archive_data (Bash command failed. The command returned a non-zero exit code 127.; 197)
[2024-03-02T14:16:27.244+0000] {local_task_job_runner.py:234} INFO - Task exited with return code 1
[2024-03-02T14:16:27.259+0000] {taskinstance.py:3280} INFO - 0 downstream tasks scheduled from follow-on schedule check
