[2024-03-02T12:45:51.590+0000] {taskinstance.py:1956} INFO - Dependencies all met for dep_context=non-requeueable deps ti=<TaskInstance: task_1_dag.scrape_data_2023 scheduled__2024-03-01T00:00:00+00:00 [queued]>
[2024-03-02T12:45:51.606+0000] {taskinstance.py:1956} INFO - Dependencies all met for dep_context=requeueable deps ti=<TaskInstance: task_1_dag.scrape_data_2023 scheduled__2024-03-01T00:00:00+00:00 [queued]>
[2024-03-02T12:45:51.607+0000] {taskinstance.py:2170} INFO - Starting attempt 1 of 2
[2024-03-02T12:45:51.655+0000] {taskinstance.py:2191} INFO - Executing <Task(PythonOperator): scrape_data_2023> on 2024-03-01 00:00:00+00:00
[2024-03-02T12:45:51.668+0000] {standard_task_runner.py:60} INFO - Started process 311 to run task
[2024-03-02T12:45:51.673+0000] {standard_task_runner.py:87} INFO - Running: ['***', 'tasks', 'run', 'task_1_dag', 'scrape_data_2023', 'scheduled__2024-03-01T00:00:00+00:00', '--job-id', '336', '--raw', '--subdir', 'DAGS_FOLDER/check2.py', '--cfg-path', '/tmp/tmp7945ypdb']
[2024-03-02T12:45:51.681+0000] {standard_task_runner.py:88} INFO - Job 336: Subtask scrape_data_2023
[2024-03-02T12:45:51.771+0000] {task_command.py:423} INFO - Running <TaskInstance: task_1_dag.scrape_data_2023 scheduled__2024-03-01T00:00:00+00:00 [running]> on host 1eaaea2cde69
[2024-03-02T12:45:51.910+0000] {taskinstance.py:2480} INFO - Exporting env vars: AIRFLOW_CTX_DAG_OWNER='***' AIRFLOW_CTX_DAG_ID='task_1_dag' AIRFLOW_CTX_TASK_ID='scrape_data_2023' AIRFLOW_CTX_EXECUTION_DATE='2024-03-01T00:00:00+00:00' AIRFLOW_CTX_TRY_NUMBER='1' AIRFLOW_CTX_DAG_RUN_ID='scheduled__2024-03-01T00:00:00+00:00'
[2024-03-02T12:45:51.913+0000] {logging_mixin.py:188} INFO - cwd: /opt/***
[2024-03-02T12:45:51.914+0000] {taskinstance.py:2698} ERROR - Task failed with exception
Traceback (most recent call last):
  File "/home/airflow/.local/lib/python3.8/site-packages/airflow/models/taskinstance.py", line 433, in _execute_task
    result = execute_callable(context=context, **execute_callable_kwargs)
  File "/home/airflow/.local/lib/python3.8/site-packages/airflow/operators/python.py", line 199, in execute
    return_value = self.execute_callable()
  File "/home/airflow/.local/lib/python3.8/site-packages/airflow/operators/python.py", line 216, in execute_callable
    return self.python_callable(*self.op_args, **self.op_kwargs)
  File "/opt/airflow/dags/check2.py", line 13, in scrape_data
    os.makedirs(f'/opt/airflow-docker/data/{year}', exist_ok=True)
  File "/usr/local/lib/python3.8/os.py", line 213, in makedirs
    makedirs(head, exist_ok=exist_ok)
  File "/usr/local/lib/python3.8/os.py", line 213, in makedirs
    makedirs(head, exist_ok=exist_ok)
  File "/usr/local/lib/python3.8/os.py", line 223, in makedirs
    mkdir(name, mode)
PermissionError: [Errno 13] Permission denied: '/opt/airflow-docker'
[2024-03-02T12:45:51.926+0000] {taskinstance.py:1138} INFO - Marking task as UP_FOR_RETRY. dag_id=task_1_dag, task_id=scrape_data_2023, execution_date=20240301T000000, start_date=20240302T124551, end_date=20240302T124551
[2024-03-02T12:45:51.939+0000] {standard_task_runner.py:107} ERROR - Failed to execute job 336 for task scrape_data_2023 ([Errno 13] Permission denied: '/opt/airflow-docker'; 311)
[2024-03-02T12:45:51.970+0000] {local_task_job_runner.py:234} INFO - Task exited with return code 1
[2024-03-02T12:45:51.992+0000] {taskinstance.py:3280} INFO - 0 downstream tasks scheduled from follow-on schedule check
[2024-03-02T12:49:56.404+0000] {taskinstance.py:1956} INFO - Dependencies all met for dep_context=non-requeueable deps ti=<TaskInstance: task_1_dag.scrape_data_2023 scheduled__2024-03-01T00:00:00+00:00 [queued]>
[2024-03-02T12:49:56.412+0000] {taskinstance.py:1956} INFO - Dependencies all met for dep_context=requeueable deps ti=<TaskInstance: task_1_dag.scrape_data_2023 scheduled__2024-03-01T00:00:00+00:00 [queued]>
[2024-03-02T12:49:56.413+0000] {taskinstance.py:2170} INFO - Starting attempt 1 of 2
[2024-03-02T12:49:56.424+0000] {taskinstance.py:2191} INFO - Executing <Task(PythonOperator): scrape_data_2023> on 2024-03-01 00:00:00+00:00
[2024-03-02T12:49:56.432+0000] {standard_task_runner.py:60} INFO - Started process 382 to run task
[2024-03-02T12:49:56.436+0000] {standard_task_runner.py:87} INFO - Running: ['***', 'tasks', 'run', 'task_1_dag', 'scrape_data_2023', 'scheduled__2024-03-01T00:00:00+00:00', '--job-id', '337', '--raw', '--subdir', 'DAGS_FOLDER/check2.py', '--cfg-path', '/tmp/tmpyajfmd1l']
[2024-03-02T12:49:56.440+0000] {standard_task_runner.py:88} INFO - Job 337: Subtask scrape_data_2023
[2024-03-02T12:49:56.489+0000] {task_command.py:423} INFO - Running <TaskInstance: task_1_dag.scrape_data_2023 scheduled__2024-03-01T00:00:00+00:00 [running]> on host 1eaaea2cde69
[2024-03-02T12:49:56.558+0000] {taskinstance.py:2480} INFO - Exporting env vars: AIRFLOW_CTX_DAG_OWNER='***' AIRFLOW_CTX_DAG_ID='task_1_dag' AIRFLOW_CTX_TASK_ID='scrape_data_2023' AIRFLOW_CTX_EXECUTION_DATE='2024-03-01T00:00:00+00:00' AIRFLOW_CTX_TRY_NUMBER='1' AIRFLOW_CTX_DAG_RUN_ID='scheduled__2024-03-01T00:00:00+00:00'
[2024-03-02T12:49:56.561+0000] {logging_mixin.py:188} INFO - cwd: /opt/***
[2024-03-02T12:49:56.561+0000] {taskinstance.py:2698} ERROR - Task failed with exception
Traceback (most recent call last):
  File "/home/airflow/.local/lib/python3.8/site-packages/airflow/models/taskinstance.py", line 433, in _execute_task
    result = execute_callable(context=context, **execute_callable_kwargs)
  File "/home/airflow/.local/lib/python3.8/site-packages/airflow/operators/python.py", line 199, in execute
    return_value = self.execute_callable()
  File "/home/airflow/.local/lib/python3.8/site-packages/airflow/operators/python.py", line 216, in execute_callable
    return self.python_callable(*self.op_args, **self.op_kwargs)
  File "/opt/airflow/dags/check2.py", line 13, in scrape_data
    os.makedirs(f'/opt/airflow-docker/data/{year}', exist_ok=True)
  File "/usr/local/lib/python3.8/os.py", line 213, in makedirs
    makedirs(head, exist_ok=exist_ok)
  File "/usr/local/lib/python3.8/os.py", line 213, in makedirs
    makedirs(head, exist_ok=exist_ok)
  File "/usr/local/lib/python3.8/os.py", line 223, in makedirs
    mkdir(name, mode)
PermissionError: [Errno 13] Permission denied: '/opt/airflow-docker'
[2024-03-02T12:49:56.572+0000] {taskinstance.py:1138} INFO - Marking task as UP_FOR_RETRY. dag_id=task_1_dag, task_id=scrape_data_2023, execution_date=20240301T000000, start_date=20240302T124956, end_date=20240302T124956
[2024-03-02T12:49:56.584+0000] {standard_task_runner.py:107} ERROR - Failed to execute job 337 for task scrape_data_2023 ([Errno 13] Permission denied: '/opt/airflow-docker'; 382)
[2024-03-02T12:49:56.609+0000] {local_task_job_runner.py:234} INFO - Task exited with return code 1
[2024-03-02T12:49:56.632+0000] {taskinstance.py:3280} INFO - 0 downstream tasks scheduled from follow-on schedule check
