[2024-03-01T20:33:37.422+0000] {taskinstance.py:1956} INFO - Dependencies all met for dep_context=non-requeueable deps ti=<TaskInstance: with_bash.first_task scheduled__2024-02-15T00:00:00+00:00 [queued]>
[2024-03-01T20:33:37.437+0000] {taskinstance.py:1956} INFO - Dependencies all met for dep_context=requeueable deps ti=<TaskInstance: with_bash.first_task scheduled__2024-02-15T00:00:00+00:00 [queued]>
[2024-03-01T20:33:37.439+0000] {taskinstance.py:2170} INFO - Starting attempt 6 of 6
[2024-03-01T20:33:37.467+0000] {taskinstance.py:2191} INFO - Executing <Task(BashOperator): first_task> on 2024-02-15 00:00:00+00:00
[2024-03-01T20:33:37.482+0000] {standard_task_runner.py:60} INFO - Started process 125 to run task
[2024-03-01T20:33:37.487+0000] {standard_task_runner.py:87} INFO - Running: ['***', 'tasks', 'run', 'with_bash', 'first_task', 'scheduled__2024-02-15T00:00:00+00:00', '--job-id', '111', '--raw', '--subdir', 'DAGS_FOLDER/with_bash.py', '--cfg-path', '/tmp/tmpbhwpiri6']
[2024-03-01T20:33:37.493+0000] {standard_task_runner.py:88} INFO - Job 111: Subtask first_task
[2024-03-01T20:33:37.572+0000] {task_command.py:423} INFO - Running <TaskInstance: with_bash.first_task scheduled__2024-02-15T00:00:00+00:00 [running]> on host 6a4f9e6ed399
[2024-03-01T20:33:37.723+0000] {taskinstance.py:2480} INFO - Exporting env vars: AIRFLOW_CTX_DAG_OWNER='***' AIRFLOW_CTX_DAG_ID='with_bash' AIRFLOW_CTX_TASK_ID='first_task' AIRFLOW_CTX_EXECUTION_DATE='2024-02-15T00:00:00+00:00' AIRFLOW_CTX_TRY_NUMBER='6' AIRFLOW_CTX_DAG_RUN_ID='scheduled__2024-02-15T00:00:00+00:00'
[2024-03-01T20:33:37.728+0000] {subprocess.py:63} INFO - Tmp dir root location: /tmp
[2024-03-01T20:33:37.730+0000] {subprocess.py:75} INFO - Running command: ['/usr/bin/bash', '-c', 'Hello World']
[2024-03-01T20:33:37.764+0000] {subprocess.py:86} INFO - Output:
[2024-03-01T20:33:37.767+0000] {subprocess.py:93} INFO - /usr/bin/bash: line 1: Hello: command not found
[2024-03-01T20:33:37.769+0000] {subprocess.py:97} INFO - Command exited with return code 127
[2024-03-01T20:33:37.790+0000] {taskinstance.py:2698} ERROR - Task failed with exception
Traceback (most recent call last):
  File "/home/airflow/.local/lib/python3.8/site-packages/airflow/models/taskinstance.py", line 433, in _execute_task
    result = execute_callable(context=context, **execute_callable_kwargs)
  File "/home/airflow/.local/lib/python3.8/site-packages/airflow/operators/bash.py", line 212, in execute
    raise AirflowException(
airflow.exceptions.AirflowException: Bash command failed. The command returned a non-zero exit code 127.
[2024-03-01T20:33:37.794+0000] {taskinstance.py:1138} INFO - Marking task as FAILED. dag_id=with_bash, task_id=first_task, execution_date=20240215T000000, start_date=20240301T203337, end_date=20240301T203337
[2024-03-01T20:33:37.822+0000] {standard_task_runner.py:107} ERROR - Failed to execute job 111 for task first_task (Bash command failed. The command returned a non-zero exit code 127.; 125)
[2024-03-01T20:33:37.862+0000] {local_task_job_runner.py:234} INFO - Task exited with return code 1
[2024-03-01T20:33:37.908+0000] {taskinstance.py:3280} INFO - 0 downstream tasks scheduled from follow-on schedule check
