[2024-03-01T20:29:28.344+0000] {taskinstance.py:1956} INFO - Dependencies all met for dep_context=non-requeueable deps ti=<TaskInstance: with_bash.first_task scheduled__2024-02-04T00:00:00+00:00 [queued]>
[2024-03-01T20:29:28.356+0000] {taskinstance.py:1956} INFO - Dependencies all met for dep_context=requeueable deps ti=<TaskInstance: with_bash.first_task scheduled__2024-02-04T00:00:00+00:00 [queued]>
[2024-03-01T20:29:28.359+0000] {taskinstance.py:2170} INFO - Starting attempt 4 of 6
[2024-03-01T20:29:28.383+0000] {taskinstance.py:2191} INFO - Executing <Task(BashOperator): first_task> on 2024-02-04 00:00:00+00:00
[2024-03-01T20:29:28.396+0000] {standard_task_runner.py:60} INFO - Started process 480 to run task
[2024-03-01T20:29:28.400+0000] {standard_task_runner.py:87} INFO - Running: ['***', 'tasks', 'run', 'with_bash', 'first_task', 'scheduled__2024-02-04T00:00:00+00:00', '--job-id', '70', '--raw', '--subdir', 'DAGS_FOLDER/with_bash.py', '--cfg-path', '/tmp/tmp7m892nxj']
[2024-03-01T20:29:28.404+0000] {standard_task_runner.py:88} INFO - Job 70: Subtask first_task
[2024-03-01T20:29:28.490+0000] {task_command.py:423} INFO - Running <TaskInstance: with_bash.first_task scheduled__2024-02-04T00:00:00+00:00 [running]> on host 3ae7012c7157
[2024-03-01T20:29:28.597+0000] {taskinstance.py:2480} INFO - Exporting env vars: AIRFLOW_CTX_DAG_OWNER='***' AIRFLOW_CTX_DAG_ID='with_bash' AIRFLOW_CTX_TASK_ID='first_task' AIRFLOW_CTX_EXECUTION_DATE='2024-02-04T00:00:00+00:00' AIRFLOW_CTX_TRY_NUMBER='4' AIRFLOW_CTX_DAG_RUN_ID='scheduled__2024-02-04T00:00:00+00:00'
[2024-03-01T20:29:28.601+0000] {subprocess.py:63} INFO - Tmp dir root location: /tmp
[2024-03-01T20:29:28.603+0000] {subprocess.py:75} INFO - Running command: ['/usr/bin/bash', '-c', 'Hello World']
[2024-03-01T20:29:28.628+0000] {subprocess.py:86} INFO - Output:
[2024-03-01T20:29:28.631+0000] {subprocess.py:93} INFO - /usr/bin/bash: line 1: Hello: command not found
[2024-03-01T20:29:28.632+0000] {subprocess.py:97} INFO - Command exited with return code 127
[2024-03-01T20:29:28.647+0000] {taskinstance.py:2698} ERROR - Task failed with exception
Traceback (most recent call last):
  File "/home/airflow/.local/lib/python3.8/site-packages/airflow/models/taskinstance.py", line 433, in _execute_task
    result = execute_callable(context=context, **execute_callable_kwargs)
  File "/home/airflow/.local/lib/python3.8/site-packages/airflow/operators/bash.py", line 212, in execute
    raise AirflowException(
airflow.exceptions.AirflowException: Bash command failed. The command returned a non-zero exit code 127.
[2024-03-01T20:29:28.658+0000] {taskinstance.py:1138} INFO - Marking task as UP_FOR_RETRY. dag_id=with_bash, task_id=first_task, execution_date=20240204T000000, start_date=20240301T202928, end_date=20240301T202928
[2024-03-01T20:29:28.682+0000] {standard_task_runner.py:107} ERROR - Failed to execute job 70 for task first_task (Bash command failed. The command returned a non-zero exit code 127.; 480)
[2024-03-01T20:29:28.740+0000] {local_task_job_runner.py:234} INFO - Task exited with return code 1
[2024-03-01T20:29:28.779+0000] {taskinstance.py:3280} INFO - 0 downstream tasks scheduled from follow-on schedule check
