[2024-03-09T15:25:42.231+0000] {taskinstance.py:1956} INFO - Dependencies all met for dep_context=non-requeueable deps ti=<TaskInstance: task1dag.scrape_data_2018 scheduled__2024-03-08T00:00:00+00:00 [queued]>
[2024-03-09T15:25:42.289+0000] {taskinstance.py:1956} INFO - Dependencies all met for dep_context=requeueable deps ti=<TaskInstance: task1dag.scrape_data_2018 scheduled__2024-03-08T00:00:00+00:00 [queued]>
[2024-03-09T15:25:42.292+0000] {taskinstance.py:2170} INFO - Starting attempt 1 of 2
[2024-03-09T15:25:42.333+0000] {taskinstance.py:2191} INFO - Executing <Task(PythonOperator): scrape_data_2018> on 2024-03-08 00:00:00+00:00
[2024-03-09T15:25:42.361+0000] {standard_task_runner.py:60} INFO - Started process 105 to run task
[2024-03-09T15:25:42.395+0000] {standard_task_runner.py:87} INFO - Running: ['***', 'tasks', 'run', 'task1dag', 'scrape_data_2018', 'scheduled__2024-03-08T00:00:00+00:00', '--job-id', '422', '--raw', '--subdir', 'DAGS_FOLDER/task1dag.py', '--cfg-path', '/tmp/tmpdd141tbw']
[2024-03-09T15:25:42.442+0000] {standard_task_runner.py:88} INFO - Job 422: Subtask scrape_data_2018
[2024-03-09T15:25:42.969+0000] {task_command.py:423} INFO - Running <TaskInstance: task1dag.scrape_data_2018 scheduled__2024-03-08T00:00:00+00:00 [running]> on host dde2eb23f30a
[2024-03-09T15:25:43.486+0000] {taskinstance.py:2480} INFO - Exporting env vars: AIRFLOW_CTX_DAG_OWNER='***' AIRFLOW_CTX_DAG_ID='task1dag' AIRFLOW_CTX_TASK_ID='scrape_data_2018' AIRFLOW_CTX_EXECUTION_DATE='2024-03-08T00:00:00+00:00' AIRFLOW_CTX_TRY_NUMBER='1' AIRFLOW_CTX_DAG_RUN_ID='scheduled__2024-03-08T00:00:00+00:00'
[2024-03-09T15:25:43.565+0000] {logging_mixin.py:188} INFO - cwd: /opt/***
[2024-03-09T15:26:35.934+0000] {python.py:201} INFO - Done. Returned value was: None
[2024-03-09T15:26:36.014+0000] {taskinstance.py:1138} INFO - Marking task as SUCCESS. dag_id=task1dag, task_id=scrape_data_2018, execution_date=20240308T000000, start_date=20240309T152542, end_date=20240309T152636
[2024-03-09T15:26:36.213+0000] {local_task_job_runner.py:234} INFO - Task exited with return code 0
[2024-03-09T15:26:36.318+0000] {taskinstance.py:3280} INFO - 0 downstream tasks scheduled from follow-on schedule check
[2024-03-09T15:54:42.849+0000] {taskinstance.py:1956} INFO - Dependencies all met for dep_context=non-requeueable deps ti=<TaskInstance: task1dag.scrape_data_2018 scheduled__2024-03-08T00:00:00+00:00 [queued]>
[2024-03-09T15:54:42.868+0000] {taskinstance.py:1956} INFO - Dependencies all met for dep_context=requeueable deps ti=<TaskInstance: task1dag.scrape_data_2018 scheduled__2024-03-08T00:00:00+00:00 [queued]>
[2024-03-09T15:54:42.869+0000] {taskinstance.py:2170} INFO - Starting attempt 1 of 2
[2024-03-09T15:54:42.895+0000] {taskinstance.py:2191} INFO - Executing <Task(PythonOperator): scrape_data_2018> on 2024-03-08 00:00:00+00:00
[2024-03-09T15:54:42.909+0000] {standard_task_runner.py:60} INFO - Started process 548 to run task
[2024-03-09T15:54:42.915+0000] {standard_task_runner.py:87} INFO - Running: ['***', 'tasks', 'run', 'task1dag', 'scrape_data_2018', 'scheduled__2024-03-08T00:00:00+00:00', '--job-id', '450', '--raw', '--subdir', 'DAGS_FOLDER/task1dag.py', '--cfg-path', '/tmp/tmp0w8epb62']
[2024-03-09T15:54:42.921+0000] {standard_task_runner.py:88} INFO - Job 450: Subtask scrape_data_2018
[2024-03-09T15:54:43.031+0000] {task_command.py:423} INFO - Running <TaskInstance: task1dag.scrape_data_2018 scheduled__2024-03-08T00:00:00+00:00 [running]> on host 9ce19ff1a6f4
[2024-03-09T15:54:43.178+0000] {taskinstance.py:2480} INFO - Exporting env vars: AIRFLOW_CTX_DAG_OWNER='***' AIRFLOW_CTX_DAG_ID='task1dag' AIRFLOW_CTX_TASK_ID='scrape_data_2018' AIRFLOW_CTX_EXECUTION_DATE='2024-03-08T00:00:00+00:00' AIRFLOW_CTX_TRY_NUMBER='1' AIRFLOW_CTX_DAG_RUN_ID='scheduled__2024-03-08T00:00:00+00:00'
[2024-03-09T15:54:43.184+0000] {logging_mixin.py:188} INFO - cwd: /opt/***
[2024-03-09T15:56:34.137+0000] {python.py:201} INFO - Done. Returned value was: None
[2024-03-09T15:56:34.156+0000] {taskinstance.py:1138} INFO - Marking task as SUCCESS. dag_id=task1dag, task_id=scrape_data_2018, execution_date=20240308T000000, start_date=20240309T155442, end_date=20240309T155634
[2024-03-09T15:56:34.228+0000] {local_task_job_runner.py:234} INFO - Task exited with return code 0
[2024-03-09T15:56:34.280+0000] {taskinstance.py:3280} INFO - 0 downstream tasks scheduled from follow-on schedule check
[2024-03-09T17:20:29.515+0000] {taskinstance.py:1956} INFO - Dependencies all met for dep_context=non-requeueable deps ti=<TaskInstance: task1dag.scrape_data_2018 scheduled__2024-03-08T00:00:00+00:00 [queued]>
[2024-03-09T17:20:29.524+0000] {taskinstance.py:1956} INFO - Dependencies all met for dep_context=requeueable deps ti=<TaskInstance: task1dag.scrape_data_2018 scheduled__2024-03-08T00:00:00+00:00 [queued]>
[2024-03-09T17:20:29.525+0000] {taskinstance.py:2170} INFO - Starting attempt 1 of 2
[2024-03-09T17:20:29.547+0000] {taskinstance.py:2191} INFO - Executing <Task(PythonOperator): scrape_data_2018> on 2024-03-08 00:00:00+00:00
[2024-03-09T17:20:29.559+0000] {standard_task_runner.py:60} INFO - Started process 1795 to run task
[2024-03-09T17:20:29.581+0000] {standard_task_runner.py:87} INFO - Running: ['***', 'tasks', 'run', 'task1dag', 'scrape_data_2018', 'scheduled__2024-03-08T00:00:00+00:00', '--job-id', '462', '--raw', '--subdir', 'DAGS_FOLDER/task1dag.py', '--cfg-path', '/tmp/tmp3yqlu3v4']
[2024-03-09T17:20:29.587+0000] {standard_task_runner.py:88} INFO - Job 462: Subtask scrape_data_2018
[2024-03-09T17:20:29.663+0000] {task_command.py:423} INFO - Running <TaskInstance: task1dag.scrape_data_2018 scheduled__2024-03-08T00:00:00+00:00 [running]> on host 9ce19ff1a6f4
[2024-03-09T17:20:29.758+0000] {taskinstance.py:2480} INFO - Exporting env vars: AIRFLOW_CTX_DAG_OWNER='***' AIRFLOW_CTX_DAG_ID='task1dag' AIRFLOW_CTX_TASK_ID='scrape_data_2018' AIRFLOW_CTX_EXECUTION_DATE='2024-03-08T00:00:00+00:00' AIRFLOW_CTX_TRY_NUMBER='1' AIRFLOW_CTX_DAG_RUN_ID='scheduled__2024-03-08T00:00:00+00:00'
[2024-03-09T17:20:29.764+0000] {logging_mixin.py:188} INFO - cwd: /opt/***
[2024-03-09T17:31:53.252+0000] {python.py:201} INFO - Done. Returned value was: None
[2024-03-09T17:31:53.269+0000] {taskinstance.py:1138} INFO - Marking task as SUCCESS. dag_id=task1dag, task_id=scrape_data_2018, execution_date=20240308T000000, start_date=20240309T172029, end_date=20240309T173153
[2024-03-09T17:31:53.323+0000] {local_task_job_runner.py:234} INFO - Task exited with return code 0
[2024-03-09T17:31:53.349+0000] {taskinstance.py:3280} INFO - 0 downstream tasks scheduled from follow-on schedule check
[2024-03-09T17:40:48.349+0000] {taskinstance.py:1956} INFO - Dependencies all met for dep_context=non-requeueable deps ti=<TaskInstance: task1dag.scrape_data_2018 scheduled__2024-03-08T00:00:00+00:00 [queued]>
[2024-03-09T17:40:48.358+0000] {taskinstance.py:1956} INFO - Dependencies all met for dep_context=requeueable deps ti=<TaskInstance: task1dag.scrape_data_2018 scheduled__2024-03-08T00:00:00+00:00 [queued]>
[2024-03-09T17:40:48.359+0000] {taskinstance.py:2170} INFO - Starting attempt 1 of 2
[2024-03-09T17:40:48.373+0000] {taskinstance.py:2191} INFO - Executing <Task(PythonOperator): scrape_data_2018> on 2024-03-08 00:00:00+00:00
[2024-03-09T17:40:48.384+0000] {standard_task_runner.py:60} INFO - Started process 2120 to run task
[2024-03-09T17:40:48.387+0000] {standard_task_runner.py:87} INFO - Running: ['***', 'tasks', 'run', 'task1dag', 'scrape_data_2018', 'scheduled__2024-03-08T00:00:00+00:00', '--job-id', '470', '--raw', '--subdir', 'DAGS_FOLDER/task1dag.py', '--cfg-path', '/tmp/tmpa6lqs0x5']
[2024-03-09T17:40:48.389+0000] {standard_task_runner.py:88} INFO - Job 470: Subtask scrape_data_2018
[2024-03-09T17:40:48.434+0000] {task_command.py:423} INFO - Running <TaskInstance: task1dag.scrape_data_2018 scheduled__2024-03-08T00:00:00+00:00 [running]> on host 9ce19ff1a6f4
[2024-03-09T17:40:48.509+0000] {taskinstance.py:2480} INFO - Exporting env vars: AIRFLOW_CTX_DAG_OWNER='***' AIRFLOW_CTX_DAG_ID='task1dag' AIRFLOW_CTX_TASK_ID='scrape_data_2018' AIRFLOW_CTX_EXECUTION_DATE='2024-03-08T00:00:00+00:00' AIRFLOW_CTX_TRY_NUMBER='1' AIRFLOW_CTX_DAG_RUN_ID='scheduled__2024-03-08T00:00:00+00:00'
[2024-03-09T17:40:48.511+0000] {logging_mixin.py:188} INFO - cwd: /opt/***
[2024-03-09T17:49:37.087+0000] {python.py:201} INFO - Done. Returned value was: None
[2024-03-09T17:49:37.103+0000] {taskinstance.py:1138} INFO - Marking task as SUCCESS. dag_id=task1dag, task_id=scrape_data_2018, execution_date=20240308T000000, start_date=20240309T174048, end_date=20240309T174937
[2024-03-09T17:49:37.139+0000] {local_task_job_runner.py:234} INFO - Task exited with return code 0
[2024-03-09T17:49:37.163+0000] {taskinstance.py:3280} INFO - 0 downstream tasks scheduled from follow-on schedule check
[2024-03-09T17:58:49.720+0000] {taskinstance.py:1956} INFO - Dependencies all met for dep_context=non-requeueable deps ti=<TaskInstance: task1dag.scrape_data_2018 scheduled__2024-03-08T00:00:00+00:00 [queued]>
[2024-03-09T17:58:49.729+0000] {taskinstance.py:1956} INFO - Dependencies all met for dep_context=requeueable deps ti=<TaskInstance: task1dag.scrape_data_2018 scheduled__2024-03-08T00:00:00+00:00 [queued]>
[2024-03-09T17:58:49.729+0000] {taskinstance.py:2170} INFO - Starting attempt 1 of 1
[2024-03-09T17:58:49.744+0000] {taskinstance.py:2191} INFO - Executing <Task(PythonOperator): scrape_data_2018> on 2024-03-08 00:00:00+00:00
[2024-03-09T17:58:49.754+0000] {standard_task_runner.py:60} INFO - Started process 2405 to run task
[2024-03-09T17:58:49.757+0000] {standard_task_runner.py:87} INFO - Running: ['***', 'tasks', 'run', 'task1dag', 'scrape_data_2018', 'scheduled__2024-03-08T00:00:00+00:00', '--job-id', '477', '--raw', '--subdir', 'DAGS_FOLDER/task1dag.py', '--cfg-path', '/tmp/tmp_kzrwyhq']
[2024-03-09T17:58:49.761+0000] {standard_task_runner.py:88} INFO - Job 477: Subtask scrape_data_2018
[2024-03-09T17:58:49.807+0000] {task_command.py:423} INFO - Running <TaskInstance: task1dag.scrape_data_2018 scheduled__2024-03-08T00:00:00+00:00 [running]> on host 9ce19ff1a6f4
[2024-03-09T17:58:49.875+0000] {taskinstance.py:2480} INFO - Exporting env vars: AIRFLOW_CTX_DAG_OWNER='***' AIRFLOW_CTX_DAG_ID='task1dag' AIRFLOW_CTX_TASK_ID='scrape_data_2018' AIRFLOW_CTX_EXECUTION_DATE='2024-03-08T00:00:00+00:00' AIRFLOW_CTX_TRY_NUMBER='1' AIRFLOW_CTX_DAG_RUN_ID='scheduled__2024-03-08T00:00:00+00:00'
[2024-03-09T17:58:49.877+0000] {logging_mixin.py:188} INFO - cwd: /opt/***
[2024-03-09T18:08:09.159+0000] {python.py:201} INFO - Done. Returned value was: None
[2024-03-09T18:08:09.183+0000] {taskinstance.py:1138} INFO - Marking task as SUCCESS. dag_id=task1dag, task_id=scrape_data_2018, execution_date=20240308T000000, start_date=20240309T175849, end_date=20240309T180809
[2024-03-09T18:08:09.269+0000] {local_task_job_runner.py:234} INFO - Task exited with return code 0
[2024-03-09T18:08:09.318+0000] {taskinstance.py:3280} INFO - 0 downstream tasks scheduled from follow-on schedule check
[2024-03-09T19:25:37.557+0000] {taskinstance.py:1956} INFO - Dependencies all met for dep_context=non-requeueable deps ti=<TaskInstance: task1dag.scrape_data_2018 scheduled__2024-03-08T00:00:00+00:00 [queued]>
[2024-03-09T19:25:37.579+0000] {taskinstance.py:1956} INFO - Dependencies all met for dep_context=requeueable deps ti=<TaskInstance: task1dag.scrape_data_2018 scheduled__2024-03-08T00:00:00+00:00 [queued]>
[2024-03-09T19:25:37.580+0000] {taskinstance.py:2170} INFO - Starting attempt 1 of 1
[2024-03-09T19:25:37.631+0000] {taskinstance.py:2191} INFO - Executing <Task(PythonOperator): scrape_data_2018> on 2024-03-08 00:00:00+00:00
[2024-03-09T19:25:37.653+0000] {standard_task_runner.py:60} INFO - Started process 196 to run task
[2024-03-09T19:25:37.664+0000] {standard_task_runner.py:87} INFO - Running: ['***', 'tasks', 'run', 'task1dag', 'scrape_data_2018', 'scheduled__2024-03-08T00:00:00+00:00', '--job-id', '517', '--raw', '--subdir', 'DAGS_FOLDER/task1dag.py', '--cfg-path', '/tmp/tmpl9c2ov9h']
[2024-03-09T19:25:37.684+0000] {standard_task_runner.py:88} INFO - Job 517: Subtask scrape_data_2018
[2024-03-09T19:25:37.833+0000] {task_command.py:423} INFO - Running <TaskInstance: task1dag.scrape_data_2018 scheduled__2024-03-08T00:00:00+00:00 [running]> on host 800ade8643a5
[2024-03-09T19:25:38.052+0000] {taskinstance.py:2480} INFO - Exporting env vars: AIRFLOW_CTX_DAG_OWNER='***' AIRFLOW_CTX_DAG_ID='task1dag' AIRFLOW_CTX_TASK_ID='scrape_data_2018' AIRFLOW_CTX_EXECUTION_DATE='2024-03-08T00:00:00+00:00' AIRFLOW_CTX_TRY_NUMBER='1' AIRFLOW_CTX_DAG_RUN_ID='scheduled__2024-03-08T00:00:00+00:00'
[2024-03-09T19:25:38.056+0000] {logging_mixin.py:188} INFO - cwd: /opt/***
[2024-03-09T19:26:09.683+0000] {job.py:213} ERROR - Job heartbeat got an exception
Traceback (most recent call last):
  File "/home/airflow/.local/lib/python3.8/site-packages/sqlalchemy/engine/base.py", line 3371, in _wrap_pool_connect
    return fn()
  File "/home/airflow/.local/lib/python3.8/site-packages/sqlalchemy/pool/base.py", line 327, in connect
    return _ConnectionFairy._checkout(self)
  File "/home/airflow/.local/lib/python3.8/site-packages/sqlalchemy/pool/base.py", line 894, in _checkout
    fairy = _ConnectionRecord.checkout(pool)
  File "/home/airflow/.local/lib/python3.8/site-packages/sqlalchemy/pool/base.py", line 493, in checkout
    rec = pool._do_get()
  File "/home/airflow/.local/lib/python3.8/site-packages/sqlalchemy/pool/impl.py", line 256, in _do_get
    return self._create_connection()
  File "/home/airflow/.local/lib/python3.8/site-packages/sqlalchemy/pool/base.py", line 273, in _create_connection
    return _ConnectionRecord(self)
  File "/home/airflow/.local/lib/python3.8/site-packages/sqlalchemy/pool/base.py", line 388, in __init__
    self.__connect()
  File "/home/airflow/.local/lib/python3.8/site-packages/sqlalchemy/pool/base.py", line 691, in __connect
    pool.logger.debug("Error on connect(): %s", e)
  File "/home/airflow/.local/lib/python3.8/site-packages/sqlalchemy/util/langhelpers.py", line 70, in __exit__
    compat.raise_(
  File "/home/airflow/.local/lib/python3.8/site-packages/sqlalchemy/util/compat.py", line 211, in raise_
    raise exception
  File "/home/airflow/.local/lib/python3.8/site-packages/sqlalchemy/pool/base.py", line 686, in __connect
    self.dbapi_connection = connection = pool._invoke_creator(self)
  File "/home/airflow/.local/lib/python3.8/site-packages/sqlalchemy/engine/create.py", line 574, in connect
    return dialect.connect(*cargs, **cparams)
  File "/home/airflow/.local/lib/python3.8/site-packages/sqlalchemy/engine/default.py", line 598, in connect
    return self.dbapi.connect(*cargs, **cparams)
  File "/home/airflow/.local/lib/python3.8/site-packages/psycopg2/__init__.py", line 122, in connect
    conn = _connect(dsn, connection_factory=connection_factory, **kwasync)
psycopg2.OperationalError: could not translate host name "postgres" to address: Temporary failure in name resolution


The above exception was the direct cause of the following exception:

Traceback (most recent call last):
  File "/home/airflow/.local/lib/python3.8/site-packages/airflow/jobs/job.py", line 187, in heartbeat
    self._merge_from(Job._fetch_from_db(self, session))
  File "/home/airflow/.local/lib/python3.8/site-packages/airflow/api_internal/internal_api_call.py", line 114, in wrapper
    return func(*args, **kwargs)
  File "/home/airflow/.local/lib/python3.8/site-packages/airflow/utils/session.py", line 76, in wrapper
    return func(*args, **kwargs)
  File "/home/airflow/.local/lib/python3.8/site-packages/airflow/jobs/job.py", line 308, in _fetch_from_db
    session.merge(job)
  File "/home/airflow/.local/lib/python3.8/site-packages/sqlalchemy/orm/session.py", line 3056, in merge
    return self._merge(
  File "/home/airflow/.local/lib/python3.8/site-packages/sqlalchemy/orm/session.py", line 3136, in _merge
    merged = self.get(
  File "/home/airflow/.local/lib/python3.8/site-packages/sqlalchemy/orm/session.py", line 2853, in get
    return self._get_impl(
  File "/home/airflow/.local/lib/python3.8/site-packages/sqlalchemy/orm/session.py", line 2975, in _get_impl
    return db_load_fn(
  File "/home/airflow/.local/lib/python3.8/site-packages/sqlalchemy/orm/loading.py", line 530, in load_on_pk_identity
    session.execute(
  File "/home/airflow/.local/lib/python3.8/site-packages/sqlalchemy/orm/session.py", line 1716, in execute
    conn = self._connection_for_bind(bind)
  File "/home/airflow/.local/lib/python3.8/site-packages/sqlalchemy/orm/session.py", line 1555, in _connection_for_bind
    return self._transaction._connection_for_bind(
  File "/home/airflow/.local/lib/python3.8/site-packages/sqlalchemy/orm/session.py", line 750, in _connection_for_bind
    conn = bind.connect()
  File "/home/airflow/.local/lib/python3.8/site-packages/sqlalchemy/future/engine.py", line 412, in connect
    return super(Engine, self).connect()
  File "/home/airflow/.local/lib/python3.8/site-packages/sqlalchemy/engine/base.py", line 3325, in connect
    return self._connection_cls(self, close_with_result=close_with_result)
  File "/home/airflow/.local/lib/python3.8/site-packages/sqlalchemy/engine/base.py", line 96, in __init__
    else engine.raw_connection()
  File "/home/airflow/.local/lib/python3.8/site-packages/sqlalchemy/engine/base.py", line 3404, in raw_connection
    return self._wrap_pool_connect(self.pool.connect, _connection)
  File "/home/airflow/.local/lib/python3.8/site-packages/sqlalchemy/engine/base.py", line 3374, in _wrap_pool_connect
    Connection._handle_dbapi_exception_noconnection(
  File "/home/airflow/.local/lib/python3.8/site-packages/sqlalchemy/engine/base.py", line 2208, in _handle_dbapi_exception_noconnection
    util.raise_(
  File "/home/airflow/.local/lib/python3.8/site-packages/sqlalchemy/util/compat.py", line 211, in raise_
    raise exception
  File "/home/airflow/.local/lib/python3.8/site-packages/sqlalchemy/engine/base.py", line 3371, in _wrap_pool_connect
    return fn()
  File "/home/airflow/.local/lib/python3.8/site-packages/sqlalchemy/pool/base.py", line 327, in connect
    return _ConnectionFairy._checkout(self)
  File "/home/airflow/.local/lib/python3.8/site-packages/sqlalchemy/pool/base.py", line 894, in _checkout
    fairy = _ConnectionRecord.checkout(pool)
  File "/home/airflow/.local/lib/python3.8/site-packages/sqlalchemy/pool/base.py", line 493, in checkout
    rec = pool._do_get()
  File "/home/airflow/.local/lib/python3.8/site-packages/sqlalchemy/pool/impl.py", line 256, in _do_get
    return self._create_connection()
  File "/home/airflow/.local/lib/python3.8/site-packages/sqlalchemy/pool/base.py", line 273, in _create_connection
    return _ConnectionRecord(self)
  File "/home/airflow/.local/lib/python3.8/site-packages/sqlalchemy/pool/base.py", line 388, in __init__
    self.__connect()
  File "/home/airflow/.local/lib/python3.8/site-packages/sqlalchemy/pool/base.py", line 691, in __connect
    pool.logger.debug("Error on connect(): %s", e)
  File "/home/airflow/.local/lib/python3.8/site-packages/sqlalchemy/util/langhelpers.py", line 70, in __exit__
    compat.raise_(
  File "/home/airflow/.local/lib/python3.8/site-packages/sqlalchemy/util/compat.py", line 211, in raise_
    raise exception
  File "/home/airflow/.local/lib/python3.8/site-packages/sqlalchemy/pool/base.py", line 686, in __connect
    self.dbapi_connection = connection = pool._invoke_creator(self)
  File "/home/airflow/.local/lib/python3.8/site-packages/sqlalchemy/engine/create.py", line 574, in connect
    return dialect.connect(*cargs, **cparams)
  File "/home/airflow/.local/lib/python3.8/site-packages/sqlalchemy/engine/default.py", line 598, in connect
    return self.dbapi.connect(*cargs, **cparams)
  File "/home/airflow/.local/lib/python3.8/site-packages/psycopg2/__init__.py", line 122, in connect
    conn = _connect(dsn, connection_factory=connection_factory, **kwasync)
sqlalchemy.exc.OperationalError: (psycopg2.OperationalError) could not translate host name "postgres" to address: Temporary failure in name resolution

(Background on this error at: https://sqlalche.me/e/14/e3q8)
[2024-03-09T19:26:09.888+0000] {job.py:221} ERROR - Job heartbeat failed with error. Scheduler is in unhealthy state
[2024-03-09T19:26:31.891+0000] {job.py:221} ERROR - Job heartbeat failed with error. Scheduler is in unhealthy state
[2024-03-09T19:27:14.012+0000] {job.py:221} ERROR - Job heartbeat failed with error. Scheduler is in unhealthy state
[2024-03-09T19:28:53.861+0000] {job.py:221} ERROR - Job heartbeat failed with error. Scheduler is in unhealthy state
[2024-03-09T19:29:20.546+0000] {local_task_job_runner.py:234} INFO - Task exited with return code -9
[2024-03-09T19:29:20.811+0000] {taskinstance.py:3280} INFO - 0 downstream tasks scheduled from follow-on schedule check
[2024-03-09T19:48:36.374+0000] {taskinstance.py:1956} INFO - Dependencies all met for dep_context=non-requeueable deps ti=<TaskInstance: task1dag.scrape_data_2018 scheduled__2024-03-08T00:00:00+00:00 [queued]>
[2024-03-09T19:48:36.413+0000] {taskinstance.py:1956} INFO - Dependencies all met for dep_context=requeueable deps ti=<TaskInstance: task1dag.scrape_data_2018 scheduled__2024-03-08T00:00:00+00:00 [queued]>
[2024-03-09T19:48:36.417+0000] {taskinstance.py:2170} INFO - Starting attempt 1 of 1
[2024-03-09T19:48:36.534+0000] {taskinstance.py:2191} INFO - Executing <Task(PythonOperator): scrape_data_2018> on 2024-03-08 00:00:00+00:00
[2024-03-09T19:48:36.578+0000] {standard_task_runner.py:60} INFO - Started process 596 to run task
[2024-03-09T19:48:36.582+0000] {standard_task_runner.py:87} INFO - Running: ['***', 'tasks', 'run', 'task1dag', 'scrape_data_2018', 'scheduled__2024-03-08T00:00:00+00:00', '--job-id', '551', '--raw', '--subdir', 'DAGS_FOLDER/task1dag.py', '--cfg-path', '/tmp/tmpbk4fufkg']
[2024-03-09T19:48:36.593+0000] {standard_task_runner.py:88} INFO - Job 551: Subtask scrape_data_2018
[2024-03-09T19:48:36.805+0000] {task_command.py:423} INFO - Running <TaskInstance: task1dag.scrape_data_2018 scheduled__2024-03-08T00:00:00+00:00 [running]> on host 800ade8643a5
[2024-03-09T19:48:37.093+0000] {taskinstance.py:2480} INFO - Exporting env vars: AIRFLOW_CTX_DAG_OWNER='***' AIRFLOW_CTX_DAG_ID='task1dag' AIRFLOW_CTX_TASK_ID='scrape_data_2018' AIRFLOW_CTX_EXECUTION_DATE='2024-03-08T00:00:00+00:00' AIRFLOW_CTX_TRY_NUMBER='1' AIRFLOW_CTX_DAG_RUN_ID='scheduled__2024-03-08T00:00:00+00:00'
[2024-03-09T19:48:37.111+0000] {logging_mixin.py:188} INFO - cwd: /opt/***
[2024-03-09T19:49:45.385+0000] {job.py:213} ERROR - Job heartbeat got an exception
Traceback (most recent call last):
  File "/home/airflow/.local/lib/python3.8/site-packages/sqlalchemy/engine/base.py", line 3371, in _wrap_pool_connect
    return fn()
  File "/home/airflow/.local/lib/python3.8/site-packages/sqlalchemy/pool/base.py", line 327, in connect
    return _ConnectionFairy._checkout(self)
  File "/home/airflow/.local/lib/python3.8/site-packages/sqlalchemy/pool/base.py", line 894, in _checkout
    fairy = _ConnectionRecord.checkout(pool)
  File "/home/airflow/.local/lib/python3.8/site-packages/sqlalchemy/pool/base.py", line 493, in checkout
    rec = pool._do_get()
  File "/home/airflow/.local/lib/python3.8/site-packages/sqlalchemy/pool/impl.py", line 256, in _do_get
    return self._create_connection()
  File "/home/airflow/.local/lib/python3.8/site-packages/sqlalchemy/pool/base.py", line 273, in _create_connection
    return _ConnectionRecord(self)
  File "/home/airflow/.local/lib/python3.8/site-packages/sqlalchemy/pool/base.py", line 388, in __init__
    self.__connect()
  File "/home/airflow/.local/lib/python3.8/site-packages/sqlalchemy/pool/base.py", line 691, in __connect
    pool.logger.debug("Error on connect(): %s", e)
  File "/home/airflow/.local/lib/python3.8/site-packages/sqlalchemy/util/langhelpers.py", line 70, in __exit__
    compat.raise_(
  File "/home/airflow/.local/lib/python3.8/site-packages/sqlalchemy/util/compat.py", line 211, in raise_
    raise exception
  File "/home/airflow/.local/lib/python3.8/site-packages/sqlalchemy/pool/base.py", line 686, in __connect
    self.dbapi_connection = connection = pool._invoke_creator(self)
  File "/home/airflow/.local/lib/python3.8/site-packages/sqlalchemy/engine/create.py", line 574, in connect
    return dialect.connect(*cargs, **cparams)
  File "/home/airflow/.local/lib/python3.8/site-packages/sqlalchemy/engine/default.py", line 598, in connect
    return self.dbapi.connect(*cargs, **cparams)
  File "/home/airflow/.local/lib/python3.8/site-packages/psycopg2/__init__.py", line 122, in connect
    conn = _connect(dsn, connection_factory=connection_factory, **kwasync)
psycopg2.OperationalError: could not translate host name "postgres" to address: Temporary failure in name resolution


The above exception was the direct cause of the following exception:

Traceback (most recent call last):
  File "/home/airflow/.local/lib/python3.8/site-packages/airflow/jobs/job.py", line 187, in heartbeat
    self._merge_from(Job._fetch_from_db(self, session))
  File "/home/airflow/.local/lib/python3.8/site-packages/airflow/api_internal/internal_api_call.py", line 114, in wrapper
    return func(*args, **kwargs)
  File "/home/airflow/.local/lib/python3.8/site-packages/airflow/utils/session.py", line 76, in wrapper
    return func(*args, **kwargs)
  File "/home/airflow/.local/lib/python3.8/site-packages/airflow/jobs/job.py", line 308, in _fetch_from_db
    session.merge(job)
  File "/home/airflow/.local/lib/python3.8/site-packages/sqlalchemy/orm/session.py", line 3056, in merge
    return self._merge(
  File "/home/airflow/.local/lib/python3.8/site-packages/sqlalchemy/orm/session.py", line 3136, in _merge
    merged = self.get(
  File "/home/airflow/.local/lib/python3.8/site-packages/sqlalchemy/orm/session.py", line 2853, in get
    return self._get_impl(
  File "/home/airflow/.local/lib/python3.8/site-packages/sqlalchemy/orm/session.py", line 2975, in _get_impl
    return db_load_fn(
  File "/home/airflow/.local/lib/python3.8/site-packages/sqlalchemy/orm/loading.py", line 530, in load_on_pk_identity
    session.execute(
  File "/home/airflow/.local/lib/python3.8/site-packages/sqlalchemy/orm/session.py", line 1716, in execute
    conn = self._connection_for_bind(bind)
  File "/home/airflow/.local/lib/python3.8/site-packages/sqlalchemy/orm/session.py", line 1555, in _connection_for_bind
    return self._transaction._connection_for_bind(
  File "/home/airflow/.local/lib/python3.8/site-packages/sqlalchemy/orm/session.py", line 750, in _connection_for_bind
    conn = bind.connect()
  File "/home/airflow/.local/lib/python3.8/site-packages/sqlalchemy/future/engine.py", line 412, in connect
    return super(Engine, self).connect()
  File "/home/airflow/.local/lib/python3.8/site-packages/sqlalchemy/engine/base.py", line 3325, in connect
    return self._connection_cls(self, close_with_result=close_with_result)
  File "/home/airflow/.local/lib/python3.8/site-packages/sqlalchemy/engine/base.py", line 96, in __init__
    else engine.raw_connection()
  File "/home/airflow/.local/lib/python3.8/site-packages/sqlalchemy/engine/base.py", line 3404, in raw_connection
    return self._wrap_pool_connect(self.pool.connect, _connection)
  File "/home/airflow/.local/lib/python3.8/site-packages/sqlalchemy/engine/base.py", line 3374, in _wrap_pool_connect
    Connection._handle_dbapi_exception_noconnection(
  File "/home/airflow/.local/lib/python3.8/site-packages/sqlalchemy/engine/base.py", line 2208, in _handle_dbapi_exception_noconnection
    util.raise_(
  File "/home/airflow/.local/lib/python3.8/site-packages/sqlalchemy/util/compat.py", line 211, in raise_
    raise exception
  File "/home/airflow/.local/lib/python3.8/site-packages/sqlalchemy/engine/base.py", line 3371, in _wrap_pool_connect
    return fn()
  File "/home/airflow/.local/lib/python3.8/site-packages/sqlalchemy/pool/base.py", line 327, in connect
    return _ConnectionFairy._checkout(self)
  File "/home/airflow/.local/lib/python3.8/site-packages/sqlalchemy/pool/base.py", line 894, in _checkout
    fairy = _ConnectionRecord.checkout(pool)
  File "/home/airflow/.local/lib/python3.8/site-packages/sqlalchemy/pool/base.py", line 493, in checkout
    rec = pool._do_get()
  File "/home/airflow/.local/lib/python3.8/site-packages/sqlalchemy/pool/impl.py", line 256, in _do_get
    return self._create_connection()
  File "/home/airflow/.local/lib/python3.8/site-packages/sqlalchemy/pool/base.py", line 273, in _create_connection
    return _ConnectionRecord(self)
  File "/home/airflow/.local/lib/python3.8/site-packages/sqlalchemy/pool/base.py", line 388, in __init__
    self.__connect()
  File "/home/airflow/.local/lib/python3.8/site-packages/sqlalchemy/pool/base.py", line 691, in __connect
    pool.logger.debug("Error on connect(): %s", e)
  File "/home/airflow/.local/lib/python3.8/site-packages/sqlalchemy/util/langhelpers.py", line 70, in __exit__
    compat.raise_(
  File "/home/airflow/.local/lib/python3.8/site-packages/sqlalchemy/util/compat.py", line 211, in raise_
    raise exception
  File "/home/airflow/.local/lib/python3.8/site-packages/sqlalchemy/pool/base.py", line 686, in __connect
    self.dbapi_connection = connection = pool._invoke_creator(self)
  File "/home/airflow/.local/lib/python3.8/site-packages/sqlalchemy/engine/create.py", line 574, in connect
    return dialect.connect(*cargs, **cparams)
  File "/home/airflow/.local/lib/python3.8/site-packages/sqlalchemy/engine/default.py", line 598, in connect
    return self.dbapi.connect(*cargs, **cparams)
  File "/home/airflow/.local/lib/python3.8/site-packages/psycopg2/__init__.py", line 122, in connect
    conn = _connect(dsn, connection_factory=connection_factory, **kwasync)
sqlalchemy.exc.OperationalError: (psycopg2.OperationalError) could not translate host name "postgres" to address: Temporary failure in name resolution

(Background on this error at: https://sqlalche.me/e/14/e3q8)
[2024-03-09T19:49:45.424+0000] {job.py:221} ERROR - Job heartbeat failed with error. Scheduler is in unhealthy state
[2024-03-09T19:50:36.629+0000] {job.py:221} ERROR - Job heartbeat failed with error. Scheduler is in unhealthy state
[2024-03-09T19:50:44.602+0000] {local_task_job_runner.py:234} INFO - Task exited with return code -9
[2024-03-09T19:50:44.711+0000] {taskinstance.py:3280} INFO - 0 downstream tasks scheduled from follow-on schedule check
[2024-03-09T19:58:21.421+0000] {taskinstance.py:1956} INFO - Dependencies all met for dep_context=non-requeueable deps ti=<TaskInstance: task1dag.scrape_data_2018 scheduled__2024-03-08T00:00:00+00:00 [queued]>
[2024-03-09T19:58:21.442+0000] {taskinstance.py:1956} INFO - Dependencies all met for dep_context=requeueable deps ti=<TaskInstance: task1dag.scrape_data_2018 scheduled__2024-03-08T00:00:00+00:00 [queued]>
[2024-03-09T19:58:21.443+0000] {taskinstance.py:2170} INFO - Starting attempt 1 of 1
[2024-03-09T19:58:21.481+0000] {taskinstance.py:2191} INFO - Executing <Task(PythonOperator): scrape_data_2018> on 2024-03-08 00:00:00+00:00
[2024-03-09T19:58:21.525+0000] {standard_task_runner.py:60} INFO - Started process 201 to run task
[2024-03-09T19:58:21.543+0000] {standard_task_runner.py:87} INFO - Running: ['***', 'tasks', 'run', 'task1dag', 'scrape_data_2018', 'scheduled__2024-03-08T00:00:00+00:00', '--job-id', '586', '--raw', '--subdir', 'DAGS_FOLDER/task1dag.py', '--cfg-path', '/tmp/tmpmvxq2nxu']
[2024-03-09T19:58:21.551+0000] {standard_task_runner.py:88} INFO - Job 586: Subtask scrape_data_2018
[2024-03-09T19:58:21.707+0000] {task_command.py:423} INFO - Running <TaskInstance: task1dag.scrape_data_2018 scheduled__2024-03-08T00:00:00+00:00 [running]> on host 43465f8902fb
[2024-03-09T19:58:21.934+0000] {taskinstance.py:2480} INFO - Exporting env vars: AIRFLOW_CTX_DAG_OWNER='***' AIRFLOW_CTX_DAG_ID='task1dag' AIRFLOW_CTX_TASK_ID='scrape_data_2018' AIRFLOW_CTX_EXECUTION_DATE='2024-03-08T00:00:00+00:00' AIRFLOW_CTX_TRY_NUMBER='1' AIRFLOW_CTX_DAG_RUN_ID='scheduled__2024-03-08T00:00:00+00:00'
[2024-03-09T19:58:21.941+0000] {logging_mixin.py:188} INFO - cwd: /opt/***
[2024-03-09T19:58:53.776+0000] {job.py:213} ERROR - Job heartbeat got an exception
Traceback (most recent call last):
  File "/home/airflow/.local/lib/python3.8/site-packages/sqlalchemy/engine/base.py", line 3371, in _wrap_pool_connect
    return fn()
  File "/home/airflow/.local/lib/python3.8/site-packages/sqlalchemy/pool/base.py", line 327, in connect
    return _ConnectionFairy._checkout(self)
  File "/home/airflow/.local/lib/python3.8/site-packages/sqlalchemy/pool/base.py", line 894, in _checkout
    fairy = _ConnectionRecord.checkout(pool)
  File "/home/airflow/.local/lib/python3.8/site-packages/sqlalchemy/pool/base.py", line 493, in checkout
    rec = pool._do_get()
  File "/home/airflow/.local/lib/python3.8/site-packages/sqlalchemy/pool/impl.py", line 256, in _do_get
    return self._create_connection()
  File "/home/airflow/.local/lib/python3.8/site-packages/sqlalchemy/pool/base.py", line 273, in _create_connection
    return _ConnectionRecord(self)
  File "/home/airflow/.local/lib/python3.8/site-packages/sqlalchemy/pool/base.py", line 388, in __init__
    self.__connect()
  File "/home/airflow/.local/lib/python3.8/site-packages/sqlalchemy/pool/base.py", line 691, in __connect
    pool.logger.debug("Error on connect(): %s", e)
  File "/home/airflow/.local/lib/python3.8/site-packages/sqlalchemy/util/langhelpers.py", line 70, in __exit__
    compat.raise_(
  File "/home/airflow/.local/lib/python3.8/site-packages/sqlalchemy/util/compat.py", line 211, in raise_
    raise exception
  File "/home/airflow/.local/lib/python3.8/site-packages/sqlalchemy/pool/base.py", line 686, in __connect
    self.dbapi_connection = connection = pool._invoke_creator(self)
  File "/home/airflow/.local/lib/python3.8/site-packages/sqlalchemy/engine/create.py", line 574, in connect
    return dialect.connect(*cargs, **cparams)
  File "/home/airflow/.local/lib/python3.8/site-packages/sqlalchemy/engine/default.py", line 598, in connect
    return self.dbapi.connect(*cargs, **cparams)
  File "/home/airflow/.local/lib/python3.8/site-packages/psycopg2/__init__.py", line 122, in connect
    conn = _connect(dsn, connection_factory=connection_factory, **kwasync)
psycopg2.OperationalError: could not translate host name "postgres" to address: Temporary failure in name resolution


The above exception was the direct cause of the following exception:

Traceback (most recent call last):
  File "/home/airflow/.local/lib/python3.8/site-packages/airflow/jobs/job.py", line 187, in heartbeat
    self._merge_from(Job._fetch_from_db(self, session))
  File "/home/airflow/.local/lib/python3.8/site-packages/airflow/api_internal/internal_api_call.py", line 114, in wrapper
    return func(*args, **kwargs)
  File "/home/airflow/.local/lib/python3.8/site-packages/airflow/utils/session.py", line 76, in wrapper
    return func(*args, **kwargs)
  File "/home/airflow/.local/lib/python3.8/site-packages/airflow/jobs/job.py", line 308, in _fetch_from_db
    session.merge(job)
  File "/home/airflow/.local/lib/python3.8/site-packages/sqlalchemy/orm/session.py", line 3056, in merge
    return self._merge(
  File "/home/airflow/.local/lib/python3.8/site-packages/sqlalchemy/orm/session.py", line 3136, in _merge
    merged = self.get(
  File "/home/airflow/.local/lib/python3.8/site-packages/sqlalchemy/orm/session.py", line 2853, in get
    return self._get_impl(
  File "/home/airflow/.local/lib/python3.8/site-packages/sqlalchemy/orm/session.py", line 2975, in _get_impl
    return db_load_fn(
  File "/home/airflow/.local/lib/python3.8/site-packages/sqlalchemy/orm/loading.py", line 530, in load_on_pk_identity
    session.execute(
  File "/home/airflow/.local/lib/python3.8/site-packages/sqlalchemy/orm/session.py", line 1716, in execute
    conn = self._connection_for_bind(bind)
  File "/home/airflow/.local/lib/python3.8/site-packages/sqlalchemy/orm/session.py", line 1555, in _connection_for_bind
    return self._transaction._connection_for_bind(
  File "/home/airflow/.local/lib/python3.8/site-packages/sqlalchemy/orm/session.py", line 750, in _connection_for_bind
    conn = bind.connect()
  File "/home/airflow/.local/lib/python3.8/site-packages/sqlalchemy/future/engine.py", line 412, in connect
    return super(Engine, self).connect()
  File "/home/airflow/.local/lib/python3.8/site-packages/sqlalchemy/engine/base.py", line 3325, in connect
    return self._connection_cls(self, close_with_result=close_with_result)
  File "/home/airflow/.local/lib/python3.8/site-packages/sqlalchemy/engine/base.py", line 96, in __init__
    else engine.raw_connection()
  File "/home/airflow/.local/lib/python3.8/site-packages/sqlalchemy/engine/base.py", line 3404, in raw_connection
    return self._wrap_pool_connect(self.pool.connect, _connection)
  File "/home/airflow/.local/lib/python3.8/site-packages/sqlalchemy/engine/base.py", line 3374, in _wrap_pool_connect
    Connection._handle_dbapi_exception_noconnection(
  File "/home/airflow/.local/lib/python3.8/site-packages/sqlalchemy/engine/base.py", line 2208, in _handle_dbapi_exception_noconnection
    util.raise_(
  File "/home/airflow/.local/lib/python3.8/site-packages/sqlalchemy/util/compat.py", line 211, in raise_
    raise exception
  File "/home/airflow/.local/lib/python3.8/site-packages/sqlalchemy/engine/base.py", line 3371, in _wrap_pool_connect
    return fn()
  File "/home/airflow/.local/lib/python3.8/site-packages/sqlalchemy/pool/base.py", line 327, in connect
    return _ConnectionFairy._checkout(self)
  File "/home/airflow/.local/lib/python3.8/site-packages/sqlalchemy/pool/base.py", line 894, in _checkout
    fairy = _ConnectionRecord.checkout(pool)
  File "/home/airflow/.local/lib/python3.8/site-packages/sqlalchemy/pool/base.py", line 493, in checkout
    rec = pool._do_get()
  File "/home/airflow/.local/lib/python3.8/site-packages/sqlalchemy/pool/impl.py", line 256, in _do_get
    return self._create_connection()
  File "/home/airflow/.local/lib/python3.8/site-packages/sqlalchemy/pool/base.py", line 273, in _create_connection
    return _ConnectionRecord(self)
  File "/home/airflow/.local/lib/python3.8/site-packages/sqlalchemy/pool/base.py", line 388, in __init__
    self.__connect()
  File "/home/airflow/.local/lib/python3.8/site-packages/sqlalchemy/pool/base.py", line 691, in __connect
    pool.logger.debug("Error on connect(): %s", e)
  File "/home/airflow/.local/lib/python3.8/site-packages/sqlalchemy/util/langhelpers.py", line 70, in __exit__
    compat.raise_(
  File "/home/airflow/.local/lib/python3.8/site-packages/sqlalchemy/util/compat.py", line 211, in raise_
    raise exception
  File "/home/airflow/.local/lib/python3.8/site-packages/sqlalchemy/pool/base.py", line 686, in __connect
    self.dbapi_connection = connection = pool._invoke_creator(self)
  File "/home/airflow/.local/lib/python3.8/site-packages/sqlalchemy/engine/create.py", line 574, in connect
    return dialect.connect(*cargs, **cparams)
  File "/home/airflow/.local/lib/python3.8/site-packages/sqlalchemy/engine/default.py", line 598, in connect
    return self.dbapi.connect(*cargs, **cparams)
  File "/home/airflow/.local/lib/python3.8/site-packages/psycopg2/__init__.py", line 122, in connect
    conn = _connect(dsn, connection_factory=connection_factory, **kwasync)
sqlalchemy.exc.OperationalError: (psycopg2.OperationalError) could not translate host name "postgres" to address: Temporary failure in name resolution

(Background on this error at: https://sqlalche.me/e/14/e3q8)
[2024-03-09T19:58:56.232+0000] {job.py:221} ERROR - Job heartbeat failed with error. Scheduler is in unhealthy state
[2024-03-09T19:58:56.076+0000] {taskinstance.py:2698} ERROR - Task failed with exception
Traceback (most recent call last):
  File "/home/airflow/.local/lib/python3.8/site-packages/urllib3/connection.py", line 174, in _new_conn
    conn = connection.create_connection(
  File "/home/airflow/.local/lib/python3.8/site-packages/urllib3/util/connection.py", line 72, in create_connection
    for res in socket.getaddrinfo(host, port, family, socket.SOCK_STREAM):
  File "/usr/local/lib/python3.8/socket.py", line 918, in getaddrinfo
    for res in _socket.getaddrinfo(host, port, family, type, proto, flags):
socket.gaierror: [Errno -3] Temporary failure in name resolution

During handling of the above exception, another exception occurred:

Traceback (most recent call last):
  File "/home/airflow/.local/lib/python3.8/site-packages/urllib3/connectionpool.py", line 715, in urlopen
    httplib_response = self._make_request(
  File "/home/airflow/.local/lib/python3.8/site-packages/urllib3/connectionpool.py", line 404, in _make_request
    self._validate_conn(conn)
  File "/home/airflow/.local/lib/python3.8/site-packages/urllib3/connectionpool.py", line 1058, in _validate_conn
    conn.connect()
  File "/home/airflow/.local/lib/python3.8/site-packages/urllib3/connection.py", line 363, in connect
    self.sock = conn = self._new_conn()
  File "/home/airflow/.local/lib/python3.8/site-packages/urllib3/connection.py", line 186, in _new_conn
    raise NewConnectionError(
urllib3.exceptions.NewConnectionError: <urllib3.connection.HTTPSConnection object at 0x7efd1d40e220>: Failed to establish a new connection: [Errno -3] Temporary failure in name resolution

During handling of the above exception, another exception occurred:

Traceback (most recent call last):
  File "/home/airflow/.local/lib/python3.8/site-packages/requests/adapters.py", line 486, in send
    resp = conn.urlopen(
  File "/home/airflow/.local/lib/python3.8/site-packages/urllib3/connectionpool.py", line 799, in urlopen
    retries = retries.increment(
  File "/home/airflow/.local/lib/python3.8/site-packages/urllib3/util/retry.py", line 592, in increment
    raise MaxRetryError(_pool, url, error or ResponseError(cause))
urllib3.exceptions.MaxRetryError: HTTPSConnectionPool(host='www.ncei.noaa.gov', port=443): Max retries exceeded with url: /data/local-climatological-data/access/2018/01001099999.csv (Caused by NewConnectionError('<urllib3.connection.HTTPSConnection object at 0x7efd1d40e220>: Failed to establish a new connection: [Errno -3] Temporary failure in name resolution'))

During handling of the above exception, another exception occurred:

Traceback (most recent call last):
  File "/home/airflow/.local/lib/python3.8/site-packages/airflow/models/taskinstance.py", line 433, in _execute_task
    result = execute_callable(context=context, **execute_callable_kwargs)
  File "/home/airflow/.local/lib/python3.8/site-packages/airflow/operators/python.py", line 199, in execute
    return_value = self.execute_callable()
  File "/home/airflow/.local/lib/python3.8/site-packages/airflow/operators/python.py", line 216, in execute_callable
    return self.python_callable(*self.op_args, **self.op_kwargs)
  File "/opt/airflow/dags/task1dag.py", line 31, in scrape_data
    res = requests.get(file_url)
  File "/home/airflow/.local/lib/python3.8/site-packages/requests/api.py", line 73, in get
    return request("get", url, params=params, **kwargs)
  File "/home/airflow/.local/lib/python3.8/site-packages/requests/api.py", line 59, in request
    return session.request(method=method, url=url, **kwargs)
  File "/home/airflow/.local/lib/python3.8/site-packages/requests/sessions.py", line 589, in request
    resp = self.send(prep, **send_kwargs)
  File "/home/airflow/.local/lib/python3.8/site-packages/requests/sessions.py", line 703, in send
    r = adapter.send(request, **kwargs)
  File "/home/airflow/.local/lib/python3.8/site-packages/requests/adapters.py", line 519, in send
    raise ConnectionError(e, request=request)
requests.exceptions.ConnectionError: HTTPSConnectionPool(host='www.ncei.noaa.gov', port=443): Max retries exceeded with url: /data/local-climatological-data/access/2018/01001099999.csv (Caused by NewConnectionError('<urllib3.connection.HTTPSConnection object at 0x7efd1d40e220>: Failed to establish a new connection: [Errno -3] Temporary failure in name resolution'))
[2024-03-09T19:59:06.292+0000] {standard_task_runner.py:107} ERROR - Failed to execute job 586 for task scrape_data_2018 ((psycopg2.OperationalError) could not translate host name "postgres" to address: Temporary failure in name resolution

(Background on this error at: https://sqlalche.me/e/14/e3q8); 201)
[2024-03-09T19:59:06.689+0000] {local_task_job_runner.py:234} INFO - Task exited with return code 1
[2024-03-09T19:59:06.801+0000] {taskinstance.py:3280} INFO - 0 downstream tasks scheduled from follow-on schedule check
[2024-03-09T20:03:44.736+0000] {taskinstance.py:1956} INFO - Dependencies all met for dep_context=non-requeueable deps ti=<TaskInstance: task1dag.scrape_data_2018 scheduled__2024-03-08T00:00:00+00:00 [queued]>
[2024-03-09T20:03:44.751+0000] {taskinstance.py:1956} INFO - Dependencies all met for dep_context=requeueable deps ti=<TaskInstance: task1dag.scrape_data_2018 scheduled__2024-03-08T00:00:00+00:00 [queued]>
[2024-03-09T20:03:44.752+0000] {taskinstance.py:2170} INFO - Starting attempt 1 of 1
[2024-03-09T20:03:44.777+0000] {taskinstance.py:2191} INFO - Executing <Task(PythonOperator): scrape_data_2018> on 2024-03-08 00:00:00+00:00
[2024-03-09T20:03:44.798+0000] {standard_task_runner.py:60} INFO - Started process 328 to run task
[2024-03-09T20:03:44.807+0000] {standard_task_runner.py:87} INFO - Running: ['***', 'tasks', 'run', 'task1dag', 'scrape_data_2018', 'scheduled__2024-03-08T00:00:00+00:00', '--job-id', '608', '--raw', '--subdir', 'DAGS_FOLDER/task1dag.py', '--cfg-path', '/tmp/tmpf5b59qnp']
[2024-03-09T20:03:44.826+0000] {standard_task_runner.py:88} INFO - Job 608: Subtask scrape_data_2018
[2024-03-09T20:03:44.929+0000] {task_command.py:423} INFO - Running <TaskInstance: task1dag.scrape_data_2018 scheduled__2024-03-08T00:00:00+00:00 [running]> on host 43465f8902fb
[2024-03-09T20:03:45.108+0000] {taskinstance.py:2480} INFO - Exporting env vars: AIRFLOW_CTX_DAG_OWNER='***' AIRFLOW_CTX_DAG_ID='task1dag' AIRFLOW_CTX_TASK_ID='scrape_data_2018' AIRFLOW_CTX_EXECUTION_DATE='2024-03-08T00:00:00+00:00' AIRFLOW_CTX_TRY_NUMBER='1' AIRFLOW_CTX_DAG_RUN_ID='scheduled__2024-03-08T00:00:00+00:00'
[2024-03-09T20:03:45.117+0000] {logging_mixin.py:188} INFO - cwd: /opt/***
[2024-03-09T20:04:06.232+0000] {taskinstance.py:2698} ERROR - Task failed with exception
Traceback (most recent call last):
  File "/home/airflow/.local/lib/python3.8/site-packages/urllib3/connectionpool.py", line 715, in urlopen
    httplib_response = self._make_request(
  File "/home/airflow/.local/lib/python3.8/site-packages/urllib3/connectionpool.py", line 404, in _make_request
    self._validate_conn(conn)
  File "/home/airflow/.local/lib/python3.8/site-packages/urllib3/connectionpool.py", line 1058, in _validate_conn
    conn.connect()
  File "/home/airflow/.local/lib/python3.8/site-packages/urllib3/connection.py", line 419, in connect
    self.sock = ssl_wrap_socket(
  File "/home/airflow/.local/lib/python3.8/site-packages/urllib3/util/ssl_.py", line 449, in ssl_wrap_socket
    ssl_sock = _ssl_wrap_socket_impl(
  File "/home/airflow/.local/lib/python3.8/site-packages/urllib3/util/ssl_.py", line 493, in _ssl_wrap_socket_impl
    return ssl_context.wrap_socket(sock, server_hostname=server_hostname)
  File "/usr/local/lib/python3.8/ssl.py", line 500, in wrap_socket
    return self.sslsocket_class._create(
  File "/usr/local/lib/python3.8/ssl.py", line 1073, in _create
    self.do_handshake()
  File "/usr/local/lib/python3.8/ssl.py", line 1342, in do_handshake
    self._sslobj.do_handshake()
ssl.SSLZeroReturnError: TLS/SSL connection has been closed (EOF) (_ssl.c:1131)

During handling of the above exception, another exception occurred:

Traceback (most recent call last):
  File "/home/airflow/.local/lib/python3.8/site-packages/requests/adapters.py", line 486, in send
    resp = conn.urlopen(
  File "/home/airflow/.local/lib/python3.8/site-packages/urllib3/connectionpool.py", line 799, in urlopen
    retries = retries.increment(
  File "/home/airflow/.local/lib/python3.8/site-packages/urllib3/util/retry.py", line 592, in increment
    raise MaxRetryError(_pool, url, error or ResponseError(cause))
urllib3.exceptions.MaxRetryError: HTTPSConnectionPool(host='www.ncei.noaa.gov', port=443): Max retries exceeded with url: /data/local-climatological-data/access/2018 (Caused by SSLError(SSLZeroReturnError(6, 'TLS/SSL connection has been closed (EOF) (_ssl.c:1131)')))

During handling of the above exception, another exception occurred:

Traceback (most recent call last):
  File "/home/airflow/.local/lib/python3.8/site-packages/airflow/models/taskinstance.py", line 433, in _execute_task
    result = execute_callable(context=context, **execute_callable_kwargs)
  File "/home/airflow/.local/lib/python3.8/site-packages/airflow/operators/python.py", line 199, in execute
    return_value = self.execute_callable()
  File "/home/airflow/.local/lib/python3.8/site-packages/airflow/operators/python.py", line 216, in execute_callable
    return self.python_callable(*self.op_args, **self.op_kwargs)
  File "/opt/airflow/dags/task1dag.py", line 17, in scrape_data
    res = requests.get(url)
  File "/home/airflow/.local/lib/python3.8/site-packages/requests/api.py", line 73, in get
    return request("get", url, params=params, **kwargs)
  File "/home/airflow/.local/lib/python3.8/site-packages/requests/api.py", line 59, in request
    return session.request(method=method, url=url, **kwargs)
  File "/home/airflow/.local/lib/python3.8/site-packages/requests/sessions.py", line 589, in request
    resp = self.send(prep, **send_kwargs)
  File "/home/airflow/.local/lib/python3.8/site-packages/requests/sessions.py", line 703, in send
    r = adapter.send(request, **kwargs)
  File "/home/airflow/.local/lib/python3.8/site-packages/requests/adapters.py", line 517, in send
    raise SSLError(e, request=request)
requests.exceptions.SSLError: HTTPSConnectionPool(host='www.ncei.noaa.gov', port=443): Max retries exceeded with url: /data/local-climatological-data/access/2018 (Caused by SSLError(SSLZeroReturnError(6, 'TLS/SSL connection has been closed (EOF) (_ssl.c:1131)')))
[2024-03-09T20:04:07.456+0000] {taskinstance.py:1138} INFO - Marking task as FAILED. dag_id=task1dag, task_id=scrape_data_2018, execution_date=20240308T000000, start_date=20240309T200344, end_date=20240309T200407
[2024-03-09T20:04:07.484+0000] {standard_task_runner.py:107} ERROR - Failed to execute job 608 for task scrape_data_2018 (HTTPSConnectionPool(host='www.ncei.noaa.gov', port=443): Max retries exceeded with url: /data/local-climatological-data/access/2018 (Caused by SSLError(SSLZeroReturnError(6, 'TLS/SSL connection has been closed (EOF) (_ssl.c:1131)'))); 328)
[2024-03-09T20:04:07.501+0000] {local_task_job_runner.py:234} INFO - Task exited with return code 1
[2024-03-09T20:04:07.659+0000] {taskinstance.py:3280} INFO - 0 downstream tasks scheduled from follow-on schedule check
